2023-01-24 12:56:54.775 WARNING (SyncWorker_3) [homeassistant.loader] We found a custom integration ui_lovelace_minimalist which has not been tested by Home Assistant. This component might cause stability problems, be sure to disable it if you experience issues with Home Assistant
2023-01-24 12:56:54.775 WARNING (SyncWorker_3) [homeassistant.loader] We found a custom integration browser_mod which has not been tested by Home Assistant. This component might cause stability problems, be sure to disable it if you experience issues with Home Assistant
2023-01-24 12:56:54.775 WARNING (SyncWorker_3) [homeassistant.loader] We found a custom integration circadian_lighting which has not been tested by Home Assistant. This component might cause stability problems, be sure to disable it if you experience issues with Home Assistant
2023-01-24 12:56:54.776 WARNING (SyncWorker_3) [homeassistant.loader] We found a custom integration hacs which has not been tested by Home Assistant. This component might cause stability problems, be sure to disable it if you experience issues with Home Assistant
2023-01-24 12:57:00.912 ERROR (MainThread) [custom_components.ui_lovelace_minimalist.base] HACS Frontend repo "weather-radar-card" is not installed, See Integration Configuration.
2023-01-24 12:57:05.167 WARNING (MainThread) [homeassistant.components.homekit] The bridge Home Assistant Bridge has entity camera.blink_garage. For best performance, and to prevent unexpected unavailability, create and pair a separate HomeKit instance in accessory mode for this entity
2023-01-24 13:40:10.335 WARNING (MainThread) [homeassistant.helpers.entity] Update of alarm_control_panel.blink_garage is taking over 10 seconds
2023-01-24 13:40:10.357 WARNING (SyncWorker_2) [urllib3.connectionpool] Retrying (Retry(total=2, connect=None, read=None, redirect=None, status=None)) after connection broken by 'ReadTimeoutError("HTTPSConnectionPool(host='rest-u012.immedia-semi.com', port=443): Read timed out. (read timeout=10)")': /api/v3/accounts/296488/homescreen
2023-01-24 13:57:00.422 ERROR (MainThread) [homeassistant.helpers.entity] Update for alarm_control_panel.blink_garage fails
Traceback (most recent call last):
  File "/usr/src/homeassistant/homeassistant/helpers/entity.py", line 538, in async_update_ha_state
    await self.async_device_update()
  File "/usr/src/homeassistant/homeassistant/helpers/entity.py", line 736, in async_device_update
    raise exc
  File "/usr/local/lib/python3.10/concurrent/futures/thread.py", line 58, in run
    result = self.fn(*self.args, **self.kwargs)
  File "/usr/src/homeassistant/homeassistant/components/blink/alarm_control_panel.py", line 59, in update
    self.data.refresh()
  File "/usr/local/lib/python3.10/site-packages/blinkpy/helpers/util.py", line 144, in wrapper
    result = method(*args, *kwargs)
  File "/usr/local/lib/python3.10/site-packages/blinkpy/blinkpy.py", line 93, in refresh
    sync_module.refresh(force_cache=(force or force_cache))
  File "/usr/local/lib/python3.10/site-packages/blinkpy/sync_module.py", line 207, in refresh
    self.cameras[camera_name].update(camera_info, force_cache=force_cache)
  File "/usr/local/lib/python3.10/site-packages/blinkpy/camera.py", line 141, in update
    self.extract_config_info(config)
  File "/usr/local/lib/python3.10/site-packages/blinkpy/camera.py", line 147, in extract_config_info
    self.name = config.get("name", "unknown")
AttributeError: 'NoneType' object has no attribute 'get'
2023-01-24 14:02:00.431 ERROR (MainThread) [homeassistant.components.automation.auto_trigger_camera] Auto Trigger Camera: Error executing script. Unexpected error for call_service at pos 1: 'NoneType' object has no attribute 'get'
Traceback (most recent call last):
  File "/usr/src/homeassistant/homeassistant/helpers/script.py", line 451, in _async_step
    await getattr(self, handler)()
  File "/usr/src/homeassistant/homeassistant/helpers/script.py", line 684, in _async_call_service_step
    await service_task
  File "/usr/src/homeassistant/homeassistant/core.py", line 1755, in async_call
    task.result()
  File "/usr/src/homeassistant/homeassistant/core.py", line 1792, in _execute_service
    await cast(Callable[[ServiceCall], Awaitable[None]], handler.job.target)(
  File "/usr/src/homeassistant/homeassistant/helpers/entity_platform.py", line 787, in handle_service
    await service.entity_service_call(
  File "/usr/src/homeassistant/homeassistant/helpers/service.py", line 678, in entity_service_call
    future.result()  # pop exception if have
  File "/usr/src/homeassistant/homeassistant/helpers/entity.py", line 958, in async_request_call
    await coro
  File "/usr/src/homeassistant/homeassistant/helpers/service.py", line 715, in _handle_entity_call
    await result
  File "/usr/local/lib/python3.10/concurrent/futures/thread.py", line 58, in run
    result = self.fn(*self.args, **self.kwargs)
  File "/usr/src/homeassistant/homeassistant/components/blink/camera.py", line 84, in trigger_camera
    self.data.refresh()
  File "/usr/local/lib/python3.10/site-packages/blinkpy/helpers/util.py", line 144, in wrapper
    result = method(*args, *kwargs)
  File "/usr/local/lib/python3.10/site-packages/blinkpy/blinkpy.py", line 93, in refresh
    sync_module.refresh(force_cache=(force or force_cache))
  File "/usr/local/lib/python3.10/site-packages/blinkpy/sync_module.py", line 207, in refresh
    self.cameras[camera_name].update(camera_info, force_cache=force_cache)
  File "/usr/local/lib/python3.10/site-packages/blinkpy/camera.py", line 141, in update
    self.extract_config_info(config)
  File "/usr/local/lib/python3.10/site-packages/blinkpy/camera.py", line 147, in extract_config_info
    self.name = config.get("name", "unknown")
AttributeError: 'NoneType' object has no attribute 'get'
2023-01-24 14:02:00.433 ERROR (MainThread) [homeassistant.components.automation.auto_trigger_camera] While executing automation automation.auto_trigger_camera
Traceback (most recent call last):
  File "/usr/src/homeassistant/homeassistant/components/automation/__init__.py", line 546, in async_trigger
    await self.action_script.async_run(
  File "/usr/src/homeassistant/homeassistant/helpers/script.py", line 1524, in async_run
    await asyncio.shield(run.async_run())
  File "/usr/src/homeassistant/homeassistant/helpers/script.py", line 409, in async_run
    await self._async_step(log_exceptions=False)
  File "/usr/src/homeassistant/homeassistant/helpers/script.py", line 453, in _async_step
    self._handle_exception(
  File "/usr/src/homeassistant/homeassistant/helpers/script.py", line 476, in _handle_exception
    raise exception
  File "/usr/src/homeassistant/homeassistant/helpers/script.py", line 451, in _async_step
    await getattr(self, handler)()
  File "/usr/src/homeassistant/homeassistant/helpers/script.py", line 684, in _async_call_service_step
    await service_task
  File "/usr/src/homeassistant/homeassistant/core.py", line 1755, in async_call
    task.result()
  File "/usr/src/homeassistant/homeassistant/core.py", line 1792, in _execute_service
    await cast(Callable[[ServiceCall], Awaitable[None]], handler.job.target)(
  File "/usr/src/homeassistant/homeassistant/helpers/entity_platform.py", line 787, in handle_service
    await service.entity_service_call(
  File "/usr/src/homeassistant/homeassistant/helpers/service.py", line 678, in entity_service_call
    future.result()  # pop exception if have
  File "/usr/src/homeassistant/homeassistant/helpers/entity.py", line 958, in async_request_call
    await coro
  File "/usr/src/homeassistant/homeassistant/helpers/service.py", line 715, in _handle_entity_call
    await result
  File "/usr/local/lib/python3.10/concurrent/futures/thread.py", line 58, in run
    result = self.fn(*self.args, **self.kwargs)
  File "/usr/src/homeassistant/homeassistant/components/blink/camera.py", line 84, in trigger_camera
    self.data.refresh()
  File "/usr/local/lib/python3.10/site-packages/blinkpy/helpers/util.py", line 144, in wrapper
    result = method(*args, *kwargs)
  File "/usr/local/lib/python3.10/site-packages/blinkpy/blinkpy.py", line 93, in refresh
    sync_module.refresh(force_cache=(force or force_cache))
  File "/usr/local/lib/python3.10/site-packages/blinkpy/sync_module.py", line 207, in refresh
    self.cameras[camera_name].update(camera_info, force_cache=force_cache)
  File "/usr/local/lib/python3.10/site-packages/blinkpy/camera.py", line 141, in update
    self.extract_config_info(config)
  File "/usr/local/lib/python3.10/site-packages/blinkpy/camera.py", line 147, in extract_config_info
    self.name = config.get("name", "unknown")
AttributeError: 'NoneType' object has no attribute 'get'
2023-01-24 14:02:00.460 ERROR (MainThread) [homeassistant.helpers.entity] Update for alarm_control_panel.blink_garage fails
Traceback (most recent call last):
  File "/usr/src/homeassistant/homeassistant/helpers/entity.py", line 538, in async_update_ha_state
    await self.async_device_update()
  File "/usr/src/homeassistant/homeassistant/helpers/entity.py", line 736, in async_device_update
    raise exc
  File "/usr/local/lib/python3.10/concurrent/futures/thread.py", line 58, in run
    result = self.fn(*self.args, **self.kwargs)
  File "/usr/src/homeassistant/homeassistant/components/blink/alarm_control_panel.py", line 59, in update
    self.data.refresh()
  File "/usr/local/lib/python3.10/site-packages/blinkpy/helpers/util.py", line 144, in wrapper
    result = method(*args, *kwargs)
  File "/usr/local/lib/python3.10/site-packages/blinkpy/blinkpy.py", line 93, in refresh
    sync_module.refresh(force_cache=(force or force_cache))
  File "/usr/local/lib/python3.10/site-packages/blinkpy/sync_module.py", line 207, in refresh
    self.cameras[camera_name].update(camera_info, force_cache=force_cache)
  File "/usr/local/lib/python3.10/site-packages/blinkpy/camera.py", line 141, in update
    self.extract_config_info(config)
  File "/usr/local/lib/python3.10/site-packages/blinkpy/camera.py", line 147, in extract_config_info
    self.name = config.get("name", "unknown")
AttributeError: 'NoneType' object has no attribute 'get'
2023-01-24 14:04:00.409 ERROR (MainThread) [homeassistant.components.automation.auto_trigger_camera] Auto Trigger Camera: Error executing script. Unexpected error for call_service at pos 1: 'NoneType' object has no attribute 'get'
Traceback (most recent call last):
  File "/usr/src/homeassistant/homeassistant/helpers/script.py", line 451, in _async_step
    await getattr(self, handler)()
  File "/usr/src/homeassistant/homeassistant/helpers/script.py", line 684, in _async_call_service_step
    await service_task
  File "/usr/src/homeassistant/homeassistant/core.py", line 1755, in async_call
    task.result()
  File "/usr/src/homeassistant/homeassistant/core.py", line 1792, in _execute_service
    await cast(Callable[[ServiceCall], Awaitable[None]], handler.job.target)(
  File "/usr/src/homeassistant/homeassistant/helpers/entity_platform.py", line 787, in handle_service
    await service.entity_service_call(
  File "/usr/src/homeassistant/homeassistant/helpers/service.py", line 678, in entity_service_call
    future.result()  # pop exception if have
  File "/usr/src/homeassistant/homeassistant/helpers/entity.py", line 958, in async_request_call
    await coro
  File "/usr/src/homeassistant/homeassistant/helpers/service.py", line 715, in _handle_entity_call
    await result
  File "/usr/local/lib/python3.10/concurrent/futures/thread.py", line 58, in run
    result = self.fn(*self.args, **self.kwargs)
  File "/usr/src/homeassistant/homeassistant/components/blink/camera.py", line 84, in trigger_camera
    self.data.refresh()
  File "/usr/local/lib/python3.10/site-packages/blinkpy/helpers/util.py", line 144, in wrapper
    result = method(*args, *kwargs)
  File "/usr/local/lib/python3.10/site-packages/blinkpy/blinkpy.py", line 93, in refresh
    sync_module.refresh(force_cache=(force or force_cache))
  File "/usr/local/lib/python3.10/site-packages/blinkpy/sync_module.py", line 207, in refresh
    self.cameras[camera_name].update(camera_info, force_cache=force_cache)
  File "/usr/local/lib/python3.10/site-packages/blinkpy/camera.py", line 141, in update
    self.extract_config_info(config)
  File "/usr/local/lib/python3.10/site-packages/blinkpy/camera.py", line 147, in extract_config_info
    self.name = config.get("name", "unknown")
AttributeError: 'NoneType' object has no attribute 'get'
2023-01-24 14:04:00.410 ERROR (MainThread) [homeassistant.components.automation.auto_trigger_camera] While executing automation automation.auto_trigger_camera
Traceback (most recent call last):
  File "/usr/src/homeassistant/homeassistant/components/automation/__init__.py", line 546, in async_trigger
    await self.action_script.async_run(
  File "/usr/src/homeassistant/homeassistant/helpers/script.py", line 1524, in async_run
    await asyncio.shield(run.async_run())
  File "/usr/src/homeassistant/homeassistant/helpers/script.py", line 409, in async_run
    await self._async_step(log_exceptions=False)
  File "/usr/src/homeassistant/homeassistant/helpers/script.py", line 453, in _async_step
    self._handle_exception(
  File "/usr/src/homeassistant/homeassistant/helpers/script.py", line 476, in _handle_exception
    raise exception
  File "/usr/src/homeassistant/homeassistant/helpers/script.py", line 451, in _async_step
    await getattr(self, handler)()
  File "/usr/src/homeassistant/homeassistant/helpers/script.py", line 684, in _async_call_service_step
    await service_task
  File "/usr/src/homeassistant/homeassistant/core.py", line 1755, in async_call
    task.result()
  File "/usr/src/homeassistant/homeassistant/core.py", line 1792, in _execute_service
    await cast(Callable[[ServiceCall], Awaitable[None]], handler.job.target)(
  File "/usr/src/homeassistant/homeassistant/helpers/entity_platform.py", line 787, in handle_service
    await service.entity_service_call(
  File "/usr/src/homeassistant/homeassistant/helpers/service.py", line 678, in entity_service_call
    future.result()  # pop exception if have
  File "/usr/src/homeassistant/homeassistant/helpers/entity.py", line 958, in async_request_call
    await coro
  File "/usr/src/homeassistant/homeassistant/helpers/service.py", line 715, in _handle_entity_call
    await result
  File "/usr/local/lib/python3.10/concurrent/futures/thread.py", line 58, in run
    result = self.fn(*self.args, **self.kwargs)
  File "/usr/src/homeassistant/homeassistant/components/blink/camera.py", line 84, in trigger_camera
    self.data.refresh()
  File "/usr/local/lib/python3.10/site-packages/blinkpy/helpers/util.py", line 144, in wrapper
    result = method(*args, *kwargs)
  File "/usr/local/lib/python3.10/site-packages/blinkpy/blinkpy.py", line 93, in refresh
    sync_module.refresh(force_cache=(force or force_cache))
  File "/usr/local/lib/python3.10/site-packages/blinkpy/sync_module.py", line 207, in refresh
    self.cameras[camera_name].update(camera_info, force_cache=force_cache)
  File "/usr/local/lib/python3.10/site-packages/blinkpy/camera.py", line 141, in update
    self.extract_config_info(config)
  File "/usr/local/lib/python3.10/site-packages/blinkpy/camera.py", line 147, in extract_config_info
    self.name = config.get("name", "unknown")
AttributeError: 'NoneType' object has no attribute 'get'
2023-01-24 14:04:00.462 ERROR (MainThread) [homeassistant.helpers.entity] Update for sensor.blink_garage_temperature fails
Traceback (most recent call last):
  File "/usr/src/homeassistant/homeassistant/helpers/entity.py", line 538, in async_update_ha_state
    await self.async_device_update()
  File "/usr/src/homeassistant/homeassistant/helpers/entity.py", line 736, in async_device_update
    raise exc
  File "/usr/local/lib/python3.10/concurrent/futures/thread.py", line 58, in run
    result = self.fn(*self.args, **self.kwargs)
  File "/usr/src/homeassistant/homeassistant/components/blink/sensor.py", line 77, in update
    self.data.refresh()
  File "/usr/local/lib/python3.10/site-packages/blinkpy/helpers/util.py", line 144, in wrapper
    result = method(*args, *kwargs)
  File "/usr/local/lib/python3.10/site-packages/blinkpy/blinkpy.py", line 93, in refresh
    sync_module.refresh(force_cache=(force or force_cache))
  File "/usr/local/lib/python3.10/site-packages/blinkpy/sync_module.py", line 207, in refresh
    self.cameras[camera_name].update(camera_info, force_cache=force_cache)
  File "/usr/local/lib/python3.10/site-packages/blinkpy/camera.py", line 141, in update
    self.extract_config_info(config)
  File "/usr/local/lib/python3.10/site-packages/blinkpy/camera.py", line 147, in extract_config_info
    self.name = config.get("name", "unknown")
AttributeError: 'NoneType' object has no attribute 'get'
2023-01-24 14:04:00.469 ERROR (MainThread) [homeassistant.helpers.entity] Update for alarm_control_panel.blink_garage fails
Traceback (most recent call last):
  File "/usr/src/homeassistant/homeassistant/helpers/entity.py", line 538, in async_update_ha_state
    await self.async_device_update()
  File "/usr/src/homeassistant/homeassistant/helpers/entity.py", line 736, in async_device_update
    raise exc
  File "/usr/local/lib/python3.10/concurrent/futures/thread.py", line 58, in run
    result = self.fn(*self.args, **self.kwargs)
  File "/usr/src/homeassistant/homeassistant/components/blink/alarm_control_panel.py", line 59, in update
    self.data.refresh()
  File "/usr/local/lib/python3.10/site-packages/blinkpy/helpers/util.py", line 144, in wrapper
    result = method(*args, *kwargs)
  File "/usr/local/lib/python3.10/site-packages/blinkpy/blinkpy.py", line 93, in refresh
    sync_module.refresh(force_cache=(force or force_cache))
  File "/usr/local/lib/python3.10/site-packages/blinkpy/sync_module.py", line 207, in refresh
    self.cameras[camera_name].update(camera_info, force_cache=force_cache)
  File "/usr/local/lib/python3.10/site-packages/blinkpy/camera.py", line 141, in update
    self.extract_config_info(config)
  File "/usr/local/lib/python3.10/site-packages/blinkpy/camera.py", line 147, in extract_config_info
    self.name = config.get("name", "unknown")
AttributeError: 'NoneType' object has no attribute 'get'
2023-01-24 14:04:00.495 ERROR (MainThread) [homeassistant.helpers.entity] Update for binary_sensor.blink_garage_battery fails
Traceback (most recent call last):
  File "/usr/src/homeassistant/homeassistant/helpers/entity.py", line 538, in async_update_ha_state
    await self.async_device_update()
  File "/usr/src/homeassistant/homeassistant/helpers/entity.py", line 736, in async_device_update
    raise exc
  File "/usr/local/lib/python3.10/concurrent/futures/thread.py", line 58, in run
    result = self.fn(*self.args, **self.kwargs)
  File "/usr/src/homeassistant/homeassistant/components/blink/binary_sensor.py", line 74, in update
    self.data.refresh()
  File "/usr/local/lib/python3.10/site-packages/blinkpy/helpers/util.py", line 144, in wrapper
    result = method(*args, *kwargs)
  File "/usr/local/lib/python3.10/site-packages/blinkpy/blinkpy.py", line 93, in refresh
    sync_module.refresh(force_cache=(force or force_cache))
  File "/usr/local/lib/python3.10/site-packages/blinkpy/sync_module.py", line 207, in refresh
    self.cameras[camera_name].update(camera_info, force_cache=force_cache)
  File "/usr/local/lib/python3.10/site-packages/blinkpy/camera.py", line 141, in update
    self.extract_config_info(config)
  File "/usr/local/lib/python3.10/site-packages/blinkpy/camera.py", line 147, in extract_config_info
    self.name = config.get("name", "unknown")
AttributeError: 'NoneType' object has no attribute 'get'
2023-01-24 14:04:00.527 ERROR (MainThread) [homeassistant.helpers.entity] Update for sensor.blink_garage_wifi_signal fails
Traceback (most recent call last):
  File "/usr/src/homeassistant/homeassistant/helpers/entity.py", line 538, in async_update_ha_state
    await self.async_device_update()
  File "/usr/src/homeassistant/homeassistant/helpers/entity.py", line 736, in async_device_update
    raise exc
  File "/usr/local/lib/python3.10/concurrent/futures/thread.py", line 58, in run
    result = self.fn(*self.args, **self.kwargs)
  File "/usr/src/homeassistant/homeassistant/components/blink/sensor.py", line 77, in update
    self.data.refresh()
  File "/usr/local/lib/python3.10/site-packages/blinkpy/helpers/util.py", line 144, in wrapper
    result = method(*args, *kwargs)
  File "/usr/local/lib/python3.10/site-packages/blinkpy/blinkpy.py", line 93, in refresh
    sync_module.refresh(force_cache=(force or force_cache))
  File "/usr/local/lib/python3.10/site-packages/blinkpy/sync_module.py", line 207, in refresh
    self.cameras[camera_name].update(camera_info, force_cache=force_cache)
  File "/usr/local/lib/python3.10/site-packages/blinkpy/camera.py", line 141, in update
    self.extract_config_info(config)
  File "/usr/local/lib/python3.10/site-packages/blinkpy/camera.py", line 147, in extract_config_info
    self.name = config.get("name", "unknown")
AttributeError: 'NoneType' object has no attribute 'get'
2023-01-24 14:04:00.555 ERROR (MainThread) [homeassistant.helpers.entity] Update for binary_sensor.blink_garage_camera_armed fails
Traceback (most recent call last):
  File "/usr/src/homeassistant/homeassistant/helpers/entity.py", line 538, in async_update_ha_state
    await self.async_device_update()
  File "/usr/src/homeassistant/homeassistant/helpers/entity.py", line 736, in async_device_update
    raise exc
  File "/usr/local/lib/python3.10/concurrent/futures/thread.py", line 58, in run
    result = self.fn(*self.args, **self.kwargs)
  File "/usr/src/homeassistant/homeassistant/components/blink/binary_sensor.py", line 74, in update
    self.data.refresh()
  File "/usr/local/lib/python3.10/site-packages/blinkpy/helpers/util.py", line 144, in wrapper
    result = method(*args, *kwargs)
  File "/usr/local/lib/python3.10/site-packages/blinkpy/blinkpy.py", line 93, in refresh
    sync_module.refresh(force_cache=(force or force_cache))
  File "/usr/local/lib/python3.10/site-packages/blinkpy/sync_module.py", line 207, in refresh
    self.cameras[camera_name].update(camera_info, force_cache=force_cache)
  File "/usr/local/lib/python3.10/site-packages/blinkpy/camera.py", line 141, in update
    self.extract_config_info(config)
  File "/usr/local/lib/python3.10/site-packages/blinkpy/camera.py", line 147, in extract_config_info
    self.name = config.get("name", "unknown")
AttributeError: 'NoneType' object has no attribute 'get'
2023-01-24 14:04:00.616 ERROR (MainThread) [homeassistant.helpers.entity] Update for binary_sensor.blink_garage_motion_detected fails
Traceback (most recent call last):
  File "/usr/src/homeassistant/homeassistant/helpers/entity.py", line 538, in async_update_ha_state
    await self.async_device_update()
  File "/usr/src/homeassistant/homeassistant/helpers/entity.py", line 736, in async_device_update
    raise exc
  File "/usr/local/lib/python3.10/concurrent/futures/thread.py", line 58, in run
    result = self.fn(*self.args, **self.kwargs)
  File "/usr/src/homeassistant/homeassistant/components/blink/binary_sensor.py", line 74, in update
    self.data.refresh()
  File "/usr/local/lib/python3.10/site-packages/blinkpy/helpers/util.py", line 144, in wrapper
    result = method(*args, *kwargs)
  File "/usr/local/lib/python3.10/site-packages/blinkpy/blinkpy.py", line 93, in refresh
    sync_module.refresh(force_cache=(force or force_cache))
  File "/usr/local/lib/python3.10/site-packages/blinkpy/sync_module.py", line 207, in refresh
    self.cameras[camera_name].update(camera_info, force_cache=force_cache)
  File "/usr/local/lib/python3.10/site-packages/blinkpy/camera.py", line 141, in update
    self.extract_config_info(config)
  File "/usr/local/lib/python3.10/site-packages/blinkpy/camera.py", line 147, in extract_config_info
    self.name = config.get("name", "unknown")
AttributeError: 'NoneType' object has no attribute 'get'
2023-01-24 14:05:00.432 ERROR (MainThread) [homeassistant.components.automation.auto_trigger_camera] Auto Trigger Camera: Error executing script. Unexpected error for call_service at pos 1: 'NoneType' object has no attribute 'get'
Traceback (most recent call last):
  File "/usr/src/homeassistant/homeassistant/helpers/script.py", line 451, in _async_step
    await getattr(self, handler)()
  File "/usr/src/homeassistant/homeassistant/helpers/script.py", line 684, in _async_call_service_step
    await service_task
  File "/usr/src/homeassistant/homeassistant/core.py", line 1755, in async_call
    task.result()
  File "/usr/src/homeassistant/homeassistant/core.py", line 1792, in _execute_service
    await cast(Callable[[ServiceCall], Awaitable[None]], handler.job.target)(
  File "/usr/src/homeassistant/homeassistant/helpers/entity_platform.py", line 787, in handle_service
    await service.entity_service_call(
  File "/usr/src/homeassistant/homeassistant/helpers/service.py", line 678, in entity_service_call
    future.result()  # pop exception if have
  File "/usr/src/homeassistant/homeassistant/helpers/entity.py", line 958, in async_request_call
    await coro
  File "/usr/src/homeassistant/homeassistant/helpers/service.py", line 715, in _handle_entity_call
    await result
  File "/usr/local/lib/python3.10/concurrent/futures/thread.py", line 58, in run
    result = self.fn(*self.args, **self.kwargs)
  File "/usr/src/homeassistant/homeassistant/components/blink/camera.py", line 84, in trigger_camera
    self.data.refresh()
  File "/usr/local/lib/python3.10/site-packages/blinkpy/helpers/util.py", line 144, in wrapper
    result = method(*args, *kwargs)
  File "/usr/local/lib/python3.10/site-packages/blinkpy/blinkpy.py", line 93, in refresh
    sync_module.refresh(force_cache=(force or force_cache))
  File "/usr/local/lib/python3.10/site-packages/blinkpy/sync_module.py", line 207, in refresh
    self.cameras[camera_name].update(camera_info, force_cache=force_cache)
  File "/usr/local/lib/python3.10/site-packages/blinkpy/camera.py", line 141, in update
    self.extract_config_info(config)
  File "/usr/local/lib/python3.10/site-packages/blinkpy/camera.py", line 147, in extract_config_info
    self.name = config.get("name", "unknown")
AttributeError: 'NoneType' object has no attribute 'get'
2023-01-24 14:05:00.433 ERROR (MainThread) [homeassistant.components.automation.auto_trigger_camera] While executing automation automation.auto_trigger_camera
Traceback (most recent call last):
  File "/usr/src/homeassistant/homeassistant/components/automation/__init__.py", line 546, in async_trigger
    await self.action_script.async_run(
  File "/usr/src/homeassistant/homeassistant/helpers/script.py", line 1524, in async_run
    await asyncio.shield(run.async_run())
  File "/usr/src/homeassistant/homeassistant/helpers/script.py", line 409, in async_run
    await self._async_step(log_exceptions=False)
  File "/usr/src/homeassistant/homeassistant/helpers/script.py", line 453, in _async_step
    self._handle_exception(
  File "/usr/src/homeassistant/homeassistant/helpers/script.py", line 476, in _handle_exception
    raise exception
  File "/usr/src/homeassistant/homeassistant/helpers/script.py", line 451, in _async_step
    await getattr(self, handler)()
  File "/usr/src/homeassistant/homeassistant/helpers/script.py", line 684, in _async_call_service_step
    await service_task
  File "/usr/src/homeassistant/homeassistant/core.py", line 1755, in async_call
    task.result()
  File "/usr/src/homeassistant/homeassistant/core.py", line 1792, in _execute_service
    await cast(Callable[[ServiceCall], Awaitable[None]], handler.job.target)(
  File "/usr/src/homeassistant/homeassistant/helpers/entity_platform.py", line 787, in handle_service
    await service.entity_service_call(
  File "/usr/src/homeassistant/homeassistant/helpers/service.py", line 678, in entity_service_call
    future.result()  # pop exception if have
  File "/usr/src/homeassistant/homeassistant/helpers/entity.py", line 958, in async_request_call
    await coro
  File "/usr/src/homeassistant/homeassistant/helpers/service.py", line 715, in _handle_entity_call
    await result
  File "/usr/local/lib/python3.10/concurrent/futures/thread.py", line 58, in run
    result = self.fn(*self.args, **self.kwargs)
  File "/usr/src/homeassistant/homeassistant/components/blink/camera.py", line 84, in trigger_camera
    self.data.refresh()
  File "/usr/local/lib/python3.10/site-packages/blinkpy/helpers/util.py", line 144, in wrapper
    result = method(*args, *kwargs)
  File "/usr/local/lib/python3.10/site-packages/blinkpy/blinkpy.py", line 93, in refresh
    sync_module.refresh(force_cache=(force or force_cache))
  File "/usr/local/lib/python3.10/site-packages/blinkpy/sync_module.py", line 207, in refresh
    self.cameras[camera_name].update(camera_info, force_cache=force_cache)
  File "/usr/local/lib/python3.10/site-packages/blinkpy/camera.py", line 141, in update
    self.extract_config_info(config)
  File "/usr/local/lib/python3.10/site-packages/blinkpy/camera.py", line 147, in extract_config_info
    self.name = config.get("name", "unknown")
AttributeError: 'NoneType' object has no attribute 'get'
2023-01-24 14:06:00.417 ERROR (MainThread) [homeassistant.components.automation.auto_trigger_camera] Auto Trigger Camera: Error executing script. Unexpected error for call_service at pos 1: 'NoneType' object has no attribute 'get'
Traceback (most recent call last):
  File "/usr/src/homeassistant/homeassistant/helpers/script.py", line 451, in _async_step
    await getattr(self, handler)()
  File "/usr/src/homeassistant/homeassistant/helpers/script.py", line 684, in _async_call_service_step
    await service_task
  File "/usr/src/homeassistant/homeassistant/core.py", line 1755, in async_call
    task.result()
  File "/usr/src/homeassistant/homeassistant/core.py", line 1792, in _execute_service
    await cast(Callable[[ServiceCall], Awaitable[None]], handler.job.target)(
  File "/usr/src/homeassistant/homeassistant/helpers/entity_platform.py", line 787, in handle_service
    await service.entity_service_call(
  File "/usr/src/homeassistant/homeassistant/helpers/service.py", line 678, in entity_service_call
    future.result()  # pop exception if have
  File "/usr/src/homeassistant/homeassistant/helpers/entity.py", line 958, in async_request_call
    await coro
  File "/usr/src/homeassistant/homeassistant/helpers/service.py", line 715, in _handle_entity_call
    await result
  File "/usr/local/lib/python3.10/concurrent/futures/thread.py", line 58, in run
    result = self.fn(*self.args, **self.kwargs)
  File "/usr/src/homeassistant/homeassistant/components/blink/camera.py", line 84, in trigger_camera
    self.data.refresh()
  File "/usr/local/lib/python3.10/site-packages/blinkpy/helpers/util.py", line 144, in wrapper
    result = method(*args, *kwargs)
  File "/usr/local/lib/python3.10/site-packages/blinkpy/blinkpy.py", line 93, in refresh
    sync_module.refresh(force_cache=(force or force_cache))
  File "/usr/local/lib/python3.10/site-packages/blinkpy/sync_module.py", line 207, in refresh
    self.cameras[camera_name].update(camera_info, force_cache=force_cache)
  File "/usr/local/lib/python3.10/site-packages/blinkpy/camera.py", line 141, in update
    self.extract_config_info(config)
  File "/usr/local/lib/python3.10/site-packages/blinkpy/camera.py", line 147, in extract_config_info
    self.name = config.get("name", "unknown")
AttributeError: 'NoneType' object has no attribute 'get'
2023-01-24 14:06:00.418 ERROR (MainThread) [homeassistant.components.automation.auto_trigger_camera] While executing automation automation.auto_trigger_camera
Traceback (most recent call last):
  File "/usr/src/homeassistant/homeassistant/components/automation/__init__.py", line 546, in async_trigger
    await self.action_script.async_run(
  File "/usr/src/homeassistant/homeassistant/helpers/script.py", line 1524, in async_run
    await asyncio.shield(run.async_run())
  File "/usr/src/homeassistant/homeassistant/helpers/script.py", line 409, in async_run
    await self._async_step(log_exceptions=False)
  File "/usr/src/homeassistant/homeassistant/helpers/script.py", line 453, in _async_step
    self._handle_exception(
  File "/usr/src/homeassistant/homeassistant/helpers/script.py", line 476, in _handle_exception
    raise exception
  File "/usr/src/homeassistant/homeassistant/helpers/script.py", line 451, in _async_step
    await getattr(self, handler)()
  File "/usr/src/homeassistant/homeassistant/helpers/script.py", line 684, in _async_call_service_step
    await service_task
  File "/usr/src/homeassistant/homeassistant/core.py", line 1755, in async_call
    task.result()
  File "/usr/src/homeassistant/homeassistant/core.py", line 1792, in _execute_service
    await cast(Callable[[ServiceCall], Awaitable[None]], handler.job.target)(
  File "/usr/src/homeassistant/homeassistant/helpers/entity_platform.py", line 787, in handle_service
    await service.entity_service_call(
  File "/usr/src/homeassistant/homeassistant/helpers/service.py", line 678, in entity_service_call
    future.result()  # pop exception if have
  File "/usr/src/homeassistant/homeassistant/helpers/entity.py", line 958, in async_request_call
    await coro
  File "/usr/src/homeassistant/homeassistant/helpers/service.py", line 715, in _handle_entity_call
    await result
  File "/usr/local/lib/python3.10/concurrent/futures/thread.py", line 58, in run
    result = self.fn(*self.args, **self.kwargs)
  File "/usr/src/homeassistant/homeassistant/components/blink/camera.py", line 84, in trigger_camera
    self.data.refresh()
  File "/usr/local/lib/python3.10/site-packages/blinkpy/helpers/util.py", line 144, in wrapper
    result = method(*args, *kwargs)
  File "/usr/local/lib/python3.10/site-packages/blinkpy/blinkpy.py", line 93, in refresh
    sync_module.refresh(force_cache=(force or force_cache))
  File "/usr/local/lib/python3.10/site-packages/blinkpy/sync_module.py", line 207, in refresh
    self.cameras[camera_name].update(camera_info, force_cache=force_cache)
  File "/usr/local/lib/python3.10/site-packages/blinkpy/camera.py", line 141, in update
    self.extract_config_info(config)
  File "/usr/local/lib/python3.10/site-packages/blinkpy/camera.py", line 147, in extract_config_info
    self.name = config.get("name", "unknown")
AttributeError: 'NoneType' object has no attribute 'get'
2023-01-24 14:06:00.458 ERROR (MainThread) [homeassistant.helpers.entity] Update for binary_sensor.blink_garage_battery fails
Traceback (most recent call last):
  File "/usr/src/homeassistant/homeassistant/helpers/entity.py", line 538, in async_update_ha_state
    await self.async_device_update()
  File "/usr/src/homeassistant/homeassistant/helpers/entity.py", line 736, in async_device_update
    raise exc
  File "/usr/local/lib/python3.10/concurrent/futures/thread.py", line 58, in run
    result = self.fn(*self.args, **self.kwargs)
  File "/usr/src/homeassistant/homeassistant/components/blink/binary_sensor.py", line 74, in update
    self.data.refresh()
  File "/usr/local/lib/python3.10/site-packages/blinkpy/helpers/util.py", line 144, in wrapper
    result = method(*args, *kwargs)
  File "/usr/local/lib/python3.10/site-packages/blinkpy/blinkpy.py", line 93, in refresh
    sync_module.refresh(force_cache=(force or force_cache))
  File "/usr/local/lib/python3.10/site-packages/blinkpy/sync_module.py", line 207, in refresh
    self.cameras[camera_name].update(camera_info, force_cache=force_cache)
  File "/usr/local/lib/python3.10/site-packages/blinkpy/camera.py", line 141, in update
    self.extract_config_info(config)
  File "/usr/local/lib/python3.10/site-packages/blinkpy/camera.py", line 147, in extract_config_info
    self.name = config.get("name", "unknown")
AttributeError: 'NoneType' object has no attribute 'get'
2023-01-24 14:06:00.462 ERROR (MainThread) [homeassistant.helpers.entity] Update for sensor.blink_garage_temperature fails
Traceback (most recent call last):
  File "/usr/src/homeassistant/homeassistant/helpers/entity.py", line 538, in async_update_ha_state
    await self.async_device_update()
  File "/usr/src/homeassistant/homeassistant/helpers/entity.py", line 736, in async_device_update
    raise exc
  File "/usr/local/lib/python3.10/concurrent/futures/thread.py", line 58, in run
    result = self.fn(*self.args, **self.kwargs)
  File "/usr/src/homeassistant/homeassistant/components/blink/sensor.py", line 77, in update
    self.data.refresh()
  File "/usr/local/lib/python3.10/site-packages/blinkpy/helpers/util.py", line 144, in wrapper
    result = method(*args, *kwargs)
  File "/usr/local/lib/python3.10/site-packages/blinkpy/blinkpy.py", line 93, in refresh
    sync_module.refresh(force_cache=(force or force_cache))
  File "/usr/local/lib/python3.10/site-packages/blinkpy/sync_module.py", line 207, in refresh
    self.cameras[camera_name].update(camera_info, force_cache=force_cache)
  File "/usr/local/lib/python3.10/site-packages/blinkpy/camera.py", line 141, in update
    self.extract_config_info(config)
  File "/usr/local/lib/python3.10/site-packages/blinkpy/camera.py", line 147, in extract_config_info
    self.name = config.get("name", "unknown")
AttributeError: 'NoneType' object has no attribute 'get'
2023-01-24 14:06:00.468 ERROR (MainThread) [homeassistant.helpers.entity] Update for alarm_control_panel.blink_garage fails
Traceback (most recent call last):
  File "/usr/src/homeassistant/homeassistant/helpers/entity.py", line 538, in async_update_ha_state
    await self.async_device_update()
  File "/usr/src/homeassistant/homeassistant/helpers/entity.py", line 736, in async_device_update
    raise exc
  File "/usr/local/lib/python3.10/concurrent/futures/thread.py", line 58, in run
    result = self.fn(*self.args, **self.kwargs)
  File "/usr/src/homeassistant/homeassistant/components/blink/alarm_control_panel.py", line 59, in update
    self.data.refresh()
  File "/usr/local/lib/python3.10/site-packages/blinkpy/helpers/util.py", line 144, in wrapper
    result = method(*args, *kwargs)
  File "/usr/local/lib/python3.10/site-packages/blinkpy/blinkpy.py", line 93, in refresh
    sync_module.refresh(force_cache=(force or force_cache))
  File "/usr/local/lib/python3.10/site-packages/blinkpy/sync_module.py", line 207, in refresh
    self.cameras[camera_name].update(camera_info, force_cache=force_cache)
  File "/usr/local/lib/python3.10/site-packages/blinkpy/camera.py", line 141, in update
    self.extract_config_info(config)
  File "/usr/local/lib/python3.10/site-packages/blinkpy/camera.py", line 147, in extract_config_info
    self.name = config.get("name", "unknown")
AttributeError: 'NoneType' object has no attribute 'get'
2023-01-24 14:06:00.517 ERROR (MainThread) [homeassistant.helpers.entity] Update for binary_sensor.blink_garage_camera_armed fails
Traceback (most recent call last):
  File "/usr/src/homeassistant/homeassistant/helpers/entity.py", line 538, in async_update_ha_state
    await self.async_device_update()
  File "/usr/src/homeassistant/homeassistant/helpers/entity.py", line 736, in async_device_update
    raise exc
  File "/usr/local/lib/python3.10/concurrent/futures/thread.py", line 58, in run
    result = self.fn(*self.args, **self.kwargs)
  File "/usr/src/homeassistant/homeassistant/components/blink/binary_sensor.py", line 74, in update
    self.data.refresh()
  File "/usr/local/lib/python3.10/site-packages/blinkpy/helpers/util.py", line 144, in wrapper
    result = method(*args, *kwargs)
  File "/usr/local/lib/python3.10/site-packages/blinkpy/blinkpy.py", line 93, in refresh
    sync_module.refresh(force_cache=(force or force_cache))
  File "/usr/local/lib/python3.10/site-packages/blinkpy/sync_module.py", line 207, in refresh
    self.cameras[camera_name].update(camera_info, force_cache=force_cache)
  File "/usr/local/lib/python3.10/site-packages/blinkpy/camera.py", line 141, in update
    self.extract_config_info(config)
  File "/usr/local/lib/python3.10/site-packages/blinkpy/camera.py", line 147, in extract_config_info
    self.name = config.get("name", "unknown")
AttributeError: 'NoneType' object has no attribute 'get'
2023-01-24 14:06:00.523 ERROR (MainThread) [homeassistant.helpers.entity] Update for sensor.blink_garage_wifi_signal fails
Traceback (most recent call last):
  File "/usr/src/homeassistant/homeassistant/helpers/entity.py", line 538, in async_update_ha_state
    await self.async_device_update()
  File "/usr/src/homeassistant/homeassistant/helpers/entity.py", line 736, in async_device_update
    raise exc
  File "/usr/local/lib/python3.10/concurrent/futures/thread.py", line 58, in run
    result = self.fn(*self.args, **self.kwargs)
  File "/usr/src/homeassistant/homeassistant/components/blink/sensor.py", line 77, in update
    self.data.refresh()
  File "/usr/local/lib/python3.10/site-packages/blinkpy/helpers/util.py", line 144, in wrapper
    result = method(*args, *kwargs)
  File "/usr/local/lib/python3.10/site-packages/blinkpy/blinkpy.py", line 93, in refresh
    sync_module.refresh(force_cache=(force or force_cache))
  File "/usr/local/lib/python3.10/site-packages/blinkpy/sync_module.py", line 207, in refresh
    self.cameras[camera_name].update(camera_info, force_cache=force_cache)
  File "/usr/local/lib/python3.10/site-packages/blinkpy/camera.py", line 141, in update
    self.extract_config_info(config)
  File "/usr/local/lib/python3.10/site-packages/blinkpy/camera.py", line 147, in extract_config_info
    self.name = config.get("name", "unknown")
AttributeError: 'NoneType' object has no attribute 'get'
2023-01-24 14:06:00.580 ERROR (MainThread) [homeassistant.helpers.entity] Update for binary_sensor.blink_garage_motion_detected fails
Traceback (most recent call last):
  File "/usr/src/homeassistant/homeassistant/helpers/entity.py", line 538, in async_update_ha_state
    await self.async_device_update()
  File "/usr/src/homeassistant/homeassistant/helpers/entity.py", line 736, in async_device_update
    raise exc
  File "/usr/local/lib/python3.10/concurrent/futures/thread.py", line 58, in run
    result = self.fn(*self.args, **self.kwargs)
  File "/usr/src/homeassistant/homeassistant/components/blink/binary_sensor.py", line 74, in update
    self.data.refresh()
  File "/usr/local/lib/python3.10/site-packages/blinkpy/helpers/util.py", line 144, in wrapper
    result = method(*args, *kwargs)
  File "/usr/local/lib/python3.10/site-packages/blinkpy/blinkpy.py", line 93, in refresh
    sync_module.refresh(force_cache=(force or force_cache))
  File "/usr/local/lib/python3.10/site-packages/blinkpy/sync_module.py", line 207, in refresh
    self.cameras[camera_name].update(camera_info, force_cache=force_cache)
  File "/usr/local/lib/python3.10/site-packages/blinkpy/camera.py", line 141, in update
    self.extract_config_info(config)
  File "/usr/local/lib/python3.10/site-packages/blinkpy/camera.py", line 147, in extract_config_info
    self.name = config.get("name", "unknown")
AttributeError: 'NoneType' object has no attribute 'get'
2023-01-24 14:07:00.422 ERROR (MainThread) [homeassistant.components.automation.auto_trigger_camera] Auto Trigger Camera: Error executing script. Unexpected error for call_service at pos 1: 'NoneType' object has no attribute 'get'
Traceback (most recent call last):
  File "/usr/src/homeassistant/homeassistant/helpers/script.py", line 451, in _async_step
    await getattr(self, handler)()
  File "/usr/src/homeassistant/homeassistant/helpers/script.py", line 684, in _async_call_service_step
    await service_task
  File "/usr/src/homeassistant/homeassistant/core.py", line 1755, in async_call
    task.result()
  File "/usr/src/homeassistant/homeassistant/core.py", line 1792, in _execute_service
    await cast(Callable[[ServiceCall], Awaitable[None]], handler.job.target)(
  File "/usr/src/homeassistant/homeassistant/helpers/entity_platform.py", line 787, in handle_service
    await service.entity_service_call(
  File "/usr/src/homeassistant/homeassistant/helpers/service.py", line 678, in entity_service_call
    future.result()  # pop exception if have
  File "/usr/src/homeassistant/homeassistant/helpers/entity.py", line 958, in async_request_call
    await coro
  File "/usr/src/homeassistant/homeassistant/helpers/service.py", line 715, in _handle_entity_call
    await result
  File "/usr/local/lib/python3.10/concurrent/futures/thread.py", line 58, in run
    result = self.fn(*self.args, **self.kwargs)
  File "/usr/src/homeassistant/homeassistant/components/blink/camera.py", line 84, in trigger_camera
    self.data.refresh()
  File "/usr/local/lib/python3.10/site-packages/blinkpy/helpers/util.py", line 144, in wrapper
    result = method(*args, *kwargs)
  File "/usr/local/lib/python3.10/site-packages/blinkpy/blinkpy.py", line 93, in refresh
    sync_module.refresh(force_cache=(force or force_cache))
  File "/usr/local/lib/python3.10/site-packages/blinkpy/sync_module.py", line 207, in refresh
    self.cameras[camera_name].update(camera_info, force_cache=force_cache)
  File "/usr/local/lib/python3.10/site-packages/blinkpy/camera.py", line 141, in update
    self.extract_config_info(config)
  File "/usr/local/lib/python3.10/site-packages/blinkpy/camera.py", line 147, in extract_config_info
    self.name = config.get("name", "unknown")
AttributeError: 'NoneType' object has no attribute 'get'
2023-01-24 14:07:00.423 ERROR (MainThread) [homeassistant.components.automation.auto_trigger_camera] While executing automation automation.auto_trigger_camera
Traceback (most recent call last):
  File "/usr/src/homeassistant/homeassistant/components/automation/__init__.py", line 546, in async_trigger
    await self.action_script.async_run(
  File "/usr/src/homeassistant/homeassistant/helpers/script.py", line 1524, in async_run
    await asyncio.shield(run.async_run())
  File "/usr/src/homeassistant/homeassistant/helpers/script.py", line 409, in async_run
    await self._async_step(log_exceptions=False)
  File "/usr/src/homeassistant/homeassistant/helpers/script.py", line 453, in _async_step
    self._handle_exception(
  File "/usr/src/homeassistant/homeassistant/helpers/script.py", line 476, in _handle_exception
    raise exception
  File "/usr/src/homeassistant/homeassistant/helpers/script.py", line 451, in _async_step
    await getattr(self, handler)()
  File "/usr/src/homeassistant/homeassistant/helpers/script.py", line 684, in _async_call_service_step
    await service_task
  File "/usr/src/homeassistant/homeassistant/core.py", line 1755, in async_call
    task.result()
  File "/usr/src/homeassistant/homeassistant/core.py", line 1792, in _execute_service
    await cast(Callable[[ServiceCall], Awaitable[None]], handler.job.target)(
  File "/usr/src/homeassistant/homeassistant/helpers/entity_platform.py", line 787, in handle_service
    await service.entity_service_call(
  File "/usr/src/homeassistant/homeassistant/helpers/service.py", line 678, in entity_service_call
    future.result()  # pop exception if have
  File "/usr/src/homeassistant/homeassistant/helpers/entity.py", line 958, in async_request_call
    await coro
  File "/usr/src/homeassistant/homeassistant/helpers/service.py", line 715, in _handle_entity_call
    await result
  File "/usr/local/lib/python3.10/concurrent/futures/thread.py", line 58, in run
    result = self.fn(*self.args, **self.kwargs)
  File "/usr/src/homeassistant/homeassistant/components/blink/camera.py", line 84, in trigger_camera
    self.data.refresh()
  File "/usr/local/lib/python3.10/site-packages/blinkpy/helpers/util.py", line 144, in wrapper
    result = method(*args, *kwargs)
  File "/usr/local/lib/python3.10/site-packages/blinkpy/blinkpy.py", line 93, in refresh
    sync_module.refresh(force_cache=(force or force_cache))
  File "/usr/local/lib/python3.10/site-packages/blinkpy/sync_module.py", line 207, in refresh
    self.cameras[camera_name].update(camera_info, force_cache=force_cache)
  File "/usr/local/lib/python3.10/site-packages/blinkpy/camera.py", line 141, in update
    self.extract_config_info(config)
  File "/usr/local/lib/python3.10/site-packages/blinkpy/camera.py", line 147, in extract_config_info
    self.name = config.get("name", "unknown")
AttributeError: 'NoneType' object has no attribute 'get'
2023-01-24 14:07:00.428 ERROR (MainThread) [homeassistant.helpers.entity] Update for binary_sensor.blink_garage_battery fails
Traceback (most recent call last):
  File "/usr/src/homeassistant/homeassistant/helpers/entity.py", line 538, in async_update_ha_state
    await self.async_device_update()
  File "/usr/src/homeassistant/homeassistant/helpers/entity.py", line 736, in async_device_update
    raise exc
  File "/usr/local/lib/python3.10/concurrent/futures/thread.py", line 58, in run
    result = self.fn(*self.args, **self.kwargs)
  File "/usr/src/homeassistant/homeassistant/components/blink/binary_sensor.py", line 74, in update
    self.data.refresh()
  File "/usr/local/lib/python3.10/site-packages/blinkpy/helpers/util.py", line 144, in wrapper
    result = method(*args, *kwargs)
  File "/usr/local/lib/python3.10/site-packages/blinkpy/blinkpy.py", line 93, in refresh
    sync_module.refresh(force_cache=(force or force_cache))
  File "/usr/local/lib/python3.10/site-packages/blinkpy/sync_module.py", line 207, in refresh
    self.cameras[camera_name].update(camera_info, force_cache=force_cache)
  File "/usr/local/lib/python3.10/site-packages/blinkpy/camera.py", line 141, in update
    self.extract_config_info(config)
  File "/usr/local/lib/python3.10/site-packages/blinkpy/camera.py", line 147, in extract_config_info
    self.name = config.get("name", "unknown")
AttributeError: 'NoneType' object has no attribute 'get'
2023-01-24 14:07:00.478 ERROR (MainThread) [homeassistant.helpers.entity] Update for binary_sensor.blink_garage_camera_armed fails
Traceback (most recent call last):
  File "/usr/src/homeassistant/homeassistant/helpers/entity.py", line 538, in async_update_ha_state
    await self.async_device_update()
  File "/usr/src/homeassistant/homeassistant/helpers/entity.py", line 736, in async_device_update
    raise exc
  File "/usr/local/lib/python3.10/concurrent/futures/thread.py", line 58, in run
    result = self.fn(*self.args, **self.kwargs)
  File "/usr/src/homeassistant/homeassistant/components/blink/binary_sensor.py", line 74, in update
    self.data.refresh()
  File "/usr/local/lib/python3.10/site-packages/blinkpy/helpers/util.py", line 144, in wrapper
    result = method(*args, *kwargs)
  File "/usr/local/lib/python3.10/site-packages/blinkpy/blinkpy.py", line 93, in refresh
    sync_module.refresh(force_cache=(force or force_cache))
  File "/usr/local/lib/python3.10/site-packages/blinkpy/sync_module.py", line 207, in refresh
    self.cameras[camera_name].update(camera_info, force_cache=force_cache)
  File "/usr/local/lib/python3.10/site-packages/blinkpy/camera.py", line 141, in update
    self.extract_config_info(config)
  File "/usr/local/lib/python3.10/site-packages/blinkpy/camera.py", line 147, in extract_config_info
    self.name = config.get("name", "unknown")
AttributeError: 'NoneType' object has no attribute 'get'
2023-01-24 14:07:00.481 ERROR (MainThread) [homeassistant.helpers.entity] Update for alarm_control_panel.blink_garage fails
Traceback (most recent call last):
  File "/usr/src/homeassistant/homeassistant/helpers/entity.py", line 538, in async_update_ha_state
    await self.async_device_update()
  File "/usr/src/homeassistant/homeassistant/helpers/entity.py", line 736, in async_device_update
    raise exc
  File "/usr/local/lib/python3.10/concurrent/futures/thread.py", line 58, in run
    result = self.fn(*self.args, **self.kwargs)
  File "/usr/src/homeassistant/homeassistant/components/blink/alarm_control_panel.py", line 59, in update
    self.data.refresh()
  File "/usr/local/lib/python3.10/site-packages/blinkpy/helpers/util.py", line 144, in wrapper
    result = method(*args, *kwargs)
  File "/usr/local/lib/python3.10/site-packages/blinkpy/blinkpy.py", line 93, in refresh
    sync_module.refresh(force_cache=(force or force_cache))
  File "/usr/local/lib/python3.10/site-packages/blinkpy/sync_module.py", line 207, in refresh
    self.cameras[camera_name].update(camera_info, force_cache=force_cache)
  File "/usr/local/lib/python3.10/site-packages/blinkpy/camera.py", line 141, in update
    self.extract_config_info(config)
  File "/usr/local/lib/python3.10/site-packages/blinkpy/camera.py", line 147, in extract_config_info
    self.name = config.get("name", "unknown")
AttributeError: 'NoneType' object has no attribute 'get'
2023-01-24 14:07:00.496 ERROR (MainThread) [homeassistant.helpers.entity] Update for sensor.blink_garage_temperature fails
Traceback (most recent call last):
  File "/usr/src/homeassistant/homeassistant/helpers/entity.py", line 538, in async_update_ha_state
    await self.async_device_update()
  File "/usr/src/homeassistant/homeassistant/helpers/entity.py", line 736, in async_device_update
    raise exc
  File "/usr/local/lib/python3.10/concurrent/futures/thread.py", line 58, in run
    result = self.fn(*self.args, **self.kwargs)
  File "/usr/src/homeassistant/homeassistant/components/blink/sensor.py", line 77, in update
    self.data.refresh()
  File "/usr/local/lib/python3.10/site-packages/blinkpy/helpers/util.py", line 144, in wrapper
    result = method(*args, *kwargs)
  File "/usr/local/lib/python3.10/site-packages/blinkpy/blinkpy.py", line 93, in refresh
    sync_module.refresh(force_cache=(force or force_cache))
  File "/usr/local/lib/python3.10/site-packages/blinkpy/sync_module.py", line 207, in refresh
    self.cameras[camera_name].update(camera_info, force_cache=force_cache)
  File "/usr/local/lib/python3.10/site-packages/blinkpy/camera.py", line 141, in update
    self.extract_config_info(config)
  File "/usr/local/lib/python3.10/site-packages/blinkpy/camera.py", line 147, in extract_config_info
    self.name = config.get("name", "unknown")
AttributeError: 'NoneType' object has no attribute 'get'
2023-01-24 14:07:00.533 ERROR (MainThread) [homeassistant.helpers.entity] Update for binary_sensor.blink_garage_motion_detected fails
Traceback (most recent call last):
  File "/usr/src/homeassistant/homeassistant/helpers/entity.py", line 538, in async_update_ha_state
    await self.async_device_update()
  File "/usr/src/homeassistant/homeassistant/helpers/entity.py", line 736, in async_device_update
    raise exc
  File "/usr/local/lib/python3.10/concurrent/futures/thread.py", line 58, in run
    result = self.fn(*self.args, **self.kwargs)
  File "/usr/src/homeassistant/homeassistant/components/blink/binary_sensor.py", line 74, in update
    self.data.refresh()
  File "/usr/local/lib/python3.10/site-packages/blinkpy/helpers/util.py", line 144, in wrapper
    result = method(*args, *kwargs)
  File "/usr/local/lib/python3.10/site-packages/blinkpy/blinkpy.py", line 93, in refresh
    sync_module.refresh(force_cache=(force or force_cache))
  File "/usr/local/lib/python3.10/site-packages/blinkpy/sync_module.py", line 207, in refresh
    self.cameras[camera_name].update(camera_info, force_cache=force_cache)
  File "/usr/local/lib/python3.10/site-packages/blinkpy/camera.py", line 141, in update
    self.extract_config_info(config)
  File "/usr/local/lib/python3.10/site-packages/blinkpy/camera.py", line 147, in extract_config_info
    self.name = config.get("name", "unknown")
AttributeError: 'NoneType' object has no attribute 'get'
2023-01-24 14:07:00.556 ERROR (MainThread) [homeassistant.helpers.entity] Update for sensor.blink_garage_wifi_signal fails
Traceback (most recent call last):
  File "/usr/src/homeassistant/homeassistant/helpers/entity.py", line 538, in async_update_ha_state
    await self.async_device_update()
  File "/usr/src/homeassistant/homeassistant/helpers/entity.py", line 736, in async_device_update
    raise exc
  File "/usr/local/lib/python3.10/concurrent/futures/thread.py", line 58, in run
    result = self.fn(*self.args, **self.kwargs)
  File "/usr/src/homeassistant/homeassistant/components/blink/sensor.py", line 77, in update
    self.data.refresh()
  File "/usr/local/lib/python3.10/site-packages/blinkpy/helpers/util.py", line 144, in wrapper
    result = method(*args, *kwargs)
  File "/usr/local/lib/python3.10/site-packages/blinkpy/blinkpy.py", line 93, in refresh
    sync_module.refresh(force_cache=(force or force_cache))
  File "/usr/local/lib/python3.10/site-packages/blinkpy/sync_module.py", line 207, in refresh
    self.cameras[camera_name].update(camera_info, force_cache=force_cache)
  File "/usr/local/lib/python3.10/site-packages/blinkpy/camera.py", line 141, in update
    self.extract_config_info(config)
  File "/usr/local/lib/python3.10/site-packages/blinkpy/camera.py", line 147, in extract_config_info
    self.name = config.get("name", "unknown")
AttributeError: 'NoneType' object has no attribute 'get'
2023-01-24 14:08:00.428 ERROR (MainThread) [homeassistant.components.automation.auto_trigger_camera] Auto Trigger Camera: Error executing script. Unexpected error for call_service at pos 1: 'NoneType' object has no attribute 'get'
Traceback (most recent call last):
  File "/usr/src/homeassistant/homeassistant/helpers/script.py", line 451, in _async_step
    await getattr(self, handler)()
  File "/usr/src/homeassistant/homeassistant/helpers/script.py", line 684, in _async_call_service_step
    await service_task
  File "/usr/src/homeassistant/homeassistant/core.py", line 1755, in async_call
    task.result()
  File "/usr/src/homeassistant/homeassistant/core.py", line 1792, in _execute_service
    await cast(Callable[[ServiceCall], Awaitable[None]], handler.job.target)(
  File "/usr/src/homeassistant/homeassistant/helpers/entity_platform.py", line 787, in handle_service
    await service.entity_service_call(
  File "/usr/src/homeassistant/homeassistant/helpers/service.py", line 678, in entity_service_call
    future.result()  # pop exception if have
  File "/usr/src/homeassistant/homeassistant/helpers/entity.py", line 958, in async_request_call
    await coro
  File "/usr/src/homeassistant/homeassistant/helpers/service.py", line 715, in _handle_entity_call
    await result
  File "/usr/local/lib/python3.10/concurrent/futures/thread.py", line 58, in run
    result = self.fn(*self.args, **self.kwargs)
  File "/usr/src/homeassistant/homeassistant/components/blink/camera.py", line 84, in trigger_camera
    self.data.refresh()
  File "/usr/local/lib/python3.10/site-packages/blinkpy/helpers/util.py", line 144, in wrapper
    result = method(*args, *kwargs)
  File "/usr/local/lib/python3.10/site-packages/blinkpy/blinkpy.py", line 93, in refresh
    sync_module.refresh(force_cache=(force or force_cache))
  File "/usr/local/lib/python3.10/site-packages/blinkpy/sync_module.py", line 207, in refresh
    self.cameras[camera_name].update(camera_info, force_cache=force_cache)
  File "/usr/local/lib/python3.10/site-packages/blinkpy/camera.py", line 141, in update
    self.extract_config_info(config)
  File "/usr/local/lib/python3.10/site-packages/blinkpy/camera.py", line 147, in extract_config_info
    self.name = config.get("name", "unknown")
AttributeError: 'NoneType' object has no attribute 'get'
2023-01-24 14:08:00.432 ERROR (MainThread) [homeassistant.components.automation.auto_trigger_camera] While executing automation automation.auto_trigger_camera
Traceback (most recent call last):
  File "/usr/src/homeassistant/homeassistant/components/automation/__init__.py", line 546, in async_trigger
    await self.action_script.async_run(
  File "/usr/src/homeassistant/homeassistant/helpers/script.py", line 1524, in async_run
    await asyncio.shield(run.async_run())
  File "/usr/src/homeassistant/homeassistant/helpers/script.py", line 409, in async_run
    await self._async_step(log_exceptions=False)
  File "/usr/src/homeassistant/homeassistant/helpers/script.py", line 453, in _async_step
    self._handle_exception(
  File "/usr/src/homeassistant/homeassistant/helpers/script.py", line 476, in _handle_exception
    raise exception
  File "/usr/src/homeassistant/homeassistant/helpers/script.py", line 451, in _async_step
    await getattr(self, handler)()
  File "/usr/src/homeassistant/homeassistant/helpers/script.py", line 684, in _async_call_service_step
    await service_task
  File "/usr/src/homeassistant/homeassistant/core.py", line 1755, in async_call
    task.result()
  File "/usr/src/homeassistant/homeassistant/core.py", line 1792, in _execute_service
    await cast(Callable[[ServiceCall], Awaitable[None]], handler.job.target)(
  File "/usr/src/homeassistant/homeassistant/helpers/entity_platform.py", line 787, in handle_service
    await service.entity_service_call(
  File "/usr/src/homeassistant/homeassistant/helpers/service.py", line 678, in entity_service_call
    future.result()  # pop exception if have
  File "/usr/src/homeassistant/homeassistant/helpers/entity.py", line 958, in async_request_call
    await coro
  File "/usr/src/homeassistant/homeassistant/helpers/service.py", line 715, in _handle_entity_call
    await result
  File "/usr/local/lib/python3.10/concurrent/futures/thread.py", line 58, in run
    result = self.fn(*self.args, **self.kwargs)
  File "/usr/src/homeassistant/homeassistant/components/blink/camera.py", line 84, in trigger_camera
    self.data.refresh()
  File "/usr/local/lib/python3.10/site-packages/blinkpy/helpers/util.py", line 144, in wrapper
    result = method(*args, *kwargs)
  File "/usr/local/lib/python3.10/site-packages/blinkpy/blinkpy.py", line 93, in refresh
    sync_module.refresh(force_cache=(force or force_cache))
  File "/usr/local/lib/python3.10/site-packages/blinkpy/sync_module.py", line 207, in refresh
    self.cameras[camera_name].update(camera_info, force_cache=force_cache)
  File "/usr/local/lib/python3.10/site-packages/blinkpy/camera.py", line 141, in update
    self.extract_config_info(config)
  File "/usr/local/lib/python3.10/site-packages/blinkpy/camera.py", line 147, in extract_config_info
    self.name = config.get("name", "unknown")
AttributeError: 'NoneType' object has no attribute 'get'
2023-01-24 14:08:00.440 ERROR (MainThread) [homeassistant.helpers.entity] Update for binary_sensor.blink_garage_battery fails
Traceback (most recent call last):
  File "/usr/src/homeassistant/homeassistant/helpers/entity.py", line 538, in async_update_ha_state
    await self.async_device_update()
  File "/usr/src/homeassistant/homeassistant/helpers/entity.py", line 736, in async_device_update
    raise exc
  File "/usr/local/lib/python3.10/concurrent/futures/thread.py", line 58, in run
    result = self.fn(*self.args, **self.kwargs)
  File "/usr/src/homeassistant/homeassistant/components/blink/binary_sensor.py", line 74, in update
    self.data.refresh()
  File "/usr/local/lib/python3.10/site-packages/blinkpy/helpers/util.py", line 144, in wrapper
    result = method(*args, *kwargs)
  File "/usr/local/lib/python3.10/site-packages/blinkpy/blinkpy.py", line 93, in refresh
    sync_module.refresh(force_cache=(force or force_cache))
  File "/usr/local/lib/python3.10/site-packages/blinkpy/sync_module.py", line 207, in refresh
    self.cameras[camera_name].update(camera_info, force_cache=force_cache)
  File "/usr/local/lib/python3.10/site-packages/blinkpy/camera.py", line 141, in update
    self.extract_config_info(config)
  File "/usr/local/lib/python3.10/site-packages/blinkpy/camera.py", line 147, in extract_config_info
    self.name = config.get("name", "unknown")
AttributeError: 'NoneType' object has no attribute 'get'
2023-01-24 14:08:00.466 ERROR (MainThread) [homeassistant.helpers.entity] Update for alarm_control_panel.blink_garage fails
Traceback (most recent call last):
  File "/usr/src/homeassistant/homeassistant/helpers/entity.py", line 538, in async_update_ha_state
    await self.async_device_update()
  File "/usr/src/homeassistant/homeassistant/helpers/entity.py", line 736, in async_device_update
    raise exc
  File "/usr/local/lib/python3.10/concurrent/futures/thread.py", line 58, in run
    result = self.fn(*self.args, **self.kwargs)
  File "/usr/src/homeassistant/homeassistant/components/blink/alarm_control_panel.py", line 59, in update
    self.data.refresh()
  File "/usr/local/lib/python3.10/site-packages/blinkpy/helpers/util.py", line 144, in wrapper
    result = method(*args, *kwargs)
  File "/usr/local/lib/python3.10/site-packages/blinkpy/blinkpy.py", line 93, in refresh
    sync_module.refresh(force_cache=(force or force_cache))
  File "/usr/local/lib/python3.10/site-packages/blinkpy/sync_module.py", line 207, in refresh
    self.cameras[camera_name].update(camera_info, force_cache=force_cache)
  File "/usr/local/lib/python3.10/site-packages/blinkpy/camera.py", line 141, in update
    self.extract_config_info(config)
  File "/usr/local/lib/python3.10/site-packages/blinkpy/camera.py", line 147, in extract_config_info
    self.name = config.get("name", "unknown")
AttributeError: 'NoneType' object has no attribute 'get'
2023-01-24 14:08:00.468 ERROR (MainThread) [homeassistant.helpers.entity] Update for sensor.blink_garage_temperature fails
Traceback (most recent call last):
  File "/usr/src/homeassistant/homeassistant/helpers/entity.py", line 538, in async_update_ha_state
    await self.async_device_update()
  File "/usr/src/homeassistant/homeassistant/helpers/entity.py", line 736, in async_device_update
    raise exc
  File "/usr/local/lib/python3.10/concurrent/futures/thread.py", line 58, in run
    result = self.fn(*self.args, **self.kwargs)
  File "/usr/src/homeassistant/homeassistant/components/blink/sensor.py", line 77, in update
    self.data.refresh()
  File "/usr/local/lib/python3.10/site-packages/blinkpy/helpers/util.py", line 144, in wrapper
    result = method(*args, *kwargs)
  File "/usr/local/lib/python3.10/site-packages/blinkpy/blinkpy.py", line 93, in refresh
    sync_module.refresh(force_cache=(force or force_cache))
  File "/usr/local/lib/python3.10/site-packages/blinkpy/sync_module.py", line 207, in refresh
    self.cameras[camera_name].update(camera_info, force_cache=force_cache)
  File "/usr/local/lib/python3.10/site-packages/blinkpy/camera.py", line 141, in update
    self.extract_config_info(config)
  File "/usr/local/lib/python3.10/site-packages/blinkpy/camera.py", line 147, in extract_config_info
    self.name = config.get("name", "unknown")
AttributeError: 'NoneType' object has no attribute 'get'
2023-01-24 14:08:00.497 ERROR (MainThread) [homeassistant.helpers.entity] Update for binary_sensor.blink_garage_camera_armed fails
Traceback (most recent call last):
  File "/usr/src/homeassistant/homeassistant/helpers/entity.py", line 538, in async_update_ha_state
    await self.async_device_update()
  File "/usr/src/homeassistant/homeassistant/helpers/entity.py", line 736, in async_device_update
    raise exc
  File "/usr/local/lib/python3.10/concurrent/futures/thread.py", line 58, in run
    result = self.fn(*self.args, **self.kwargs)
  File "/usr/src/homeassistant/homeassistant/components/blink/binary_sensor.py", line 74, in update
    self.data.refresh()
  File "/usr/local/lib/python3.10/site-packages/blinkpy/helpers/util.py", line 144, in wrapper
    result = method(*args, *kwargs)
  File "/usr/local/lib/python3.10/site-packages/blinkpy/blinkpy.py", line 93, in refresh
    sync_module.refresh(force_cache=(force or force_cache))
  File "/usr/local/lib/python3.10/site-packages/blinkpy/sync_module.py", line 207, in refresh
    self.cameras[camera_name].update(camera_info, force_cache=force_cache)
  File "/usr/local/lib/python3.10/site-packages/blinkpy/camera.py", line 141, in update
    self.extract_config_info(config)
  File "/usr/local/lib/python3.10/site-packages/blinkpy/camera.py", line 147, in extract_config_info
    self.name = config.get("name", "unknown")
AttributeError: 'NoneType' object has no attribute 'get'
2023-01-24 14:08:00.521 ERROR (MainThread) [homeassistant.helpers.entity] Update for sensor.blink_garage_wifi_signal fails
Traceback (most recent call last):
  File "/usr/src/homeassistant/homeassistant/helpers/entity.py", line 538, in async_update_ha_state
    await self.async_device_update()
  File "/usr/src/homeassistant/homeassistant/helpers/entity.py", line 736, in async_device_update
    raise exc
  File "/usr/local/lib/python3.10/concurrent/futures/thread.py", line 58, in run
    result = self.fn(*self.args, **self.kwargs)
  File "/usr/src/homeassistant/homeassistant/components/blink/sensor.py", line 77, in update
    self.data.refresh()
  File "/usr/local/lib/python3.10/site-packages/blinkpy/helpers/util.py", line 144, in wrapper
    result = method(*args, *kwargs)
  File "/usr/local/lib/python3.10/site-packages/blinkpy/blinkpy.py", line 93, in refresh
    sync_module.refresh(force_cache=(force or force_cache))
  File "/usr/local/lib/python3.10/site-packages/blinkpy/sync_module.py", line 207, in refresh
    self.cameras[camera_name].update(camera_info, force_cache=force_cache)
  File "/usr/local/lib/python3.10/site-packages/blinkpy/camera.py", line 141, in update
    self.extract_config_info(config)
  File "/usr/local/lib/python3.10/site-packages/blinkpy/camera.py", line 147, in extract_config_info
    self.name = config.get("name", "unknown")
AttributeError: 'NoneType' object has no attribute 'get'
2023-01-24 14:08:00.562 ERROR (MainThread) [homeassistant.helpers.entity] Update for binary_sensor.blink_garage_motion_detected fails
Traceback (most recent call last):
  File "/usr/src/homeassistant/homeassistant/helpers/entity.py", line 538, in async_update_ha_state
    await self.async_device_update()
  File "/usr/src/homeassistant/homeassistant/helpers/entity.py", line 736, in async_device_update
    raise exc
  File "/usr/local/lib/python3.10/concurrent/futures/thread.py", line 58, in run
    result = self.fn(*self.args, **self.kwargs)
  File "/usr/src/homeassistant/homeassistant/components/blink/binary_sensor.py", line 74, in update
    self.data.refresh()
  File "/usr/local/lib/python3.10/site-packages/blinkpy/helpers/util.py", line 144, in wrapper
    result = method(*args, *kwargs)
  File "/usr/local/lib/python3.10/site-packages/blinkpy/blinkpy.py", line 93, in refresh
    sync_module.refresh(force_cache=(force or force_cache))
  File "/usr/local/lib/python3.10/site-packages/blinkpy/sync_module.py", line 207, in refresh
    self.cameras[camera_name].update(camera_info, force_cache=force_cache)
  File "/usr/local/lib/python3.10/site-packages/blinkpy/camera.py", line 141, in update
    self.extract_config_info(config)
  File "/usr/local/lib/python3.10/site-packages/blinkpy/camera.py", line 147, in extract_config_info
    self.name = config.get("name", "unknown")
AttributeError: 'NoneType' object has no attribute 'get'
2023-01-24 14:09:00.422 ERROR (MainThread) [homeassistant.components.automation.auto_trigger_camera] Auto Trigger Camera: Error executing script. Unexpected error for call_service at pos 1: 'NoneType' object has no attribute 'get'
Traceback (most recent call last):
  File "/usr/src/homeassistant/homeassistant/helpers/script.py", line 451, in _async_step
    await getattr(self, handler)()
  File "/usr/src/homeassistant/homeassistant/helpers/script.py", line 684, in _async_call_service_step
    await service_task
  File "/usr/src/homeassistant/homeassistant/core.py", line 1755, in async_call
    task.result()
  File "/usr/src/homeassistant/homeassistant/core.py", line 1792, in _execute_service
    await cast(Callable[[ServiceCall], Awaitable[None]], handler.job.target)(
  File "/usr/src/homeassistant/homeassistant/helpers/entity_platform.py", line 787, in handle_service
    await service.entity_service_call(
  File "/usr/src/homeassistant/homeassistant/helpers/service.py", line 678, in entity_service_call
    future.result()  # pop exception if have
  File "/usr/src/homeassistant/homeassistant/helpers/entity.py", line 958, in async_request_call
    await coro
  File "/usr/src/homeassistant/homeassistant/helpers/service.py", line 715, in _handle_entity_call
    await result
  File "/usr/local/lib/python3.10/concurrent/futures/thread.py", line 58, in run
    result = self.fn(*self.args, **self.kwargs)
  File "/usr/src/homeassistant/homeassistant/components/blink/camera.py", line 84, in trigger_camera
    self.data.refresh()
  File "/usr/local/lib/python3.10/site-packages/blinkpy/helpers/util.py", line 144, in wrapper
    result = method(*args, *kwargs)
  File "/usr/local/lib/python3.10/site-packages/blinkpy/blinkpy.py", line 93, in refresh
    sync_module.refresh(force_cache=(force or force_cache))
  File "/usr/local/lib/python3.10/site-packages/blinkpy/sync_module.py", line 207, in refresh
    self.cameras[camera_name].update(camera_info, force_cache=force_cache)
  File "/usr/local/lib/python3.10/site-packages/blinkpy/camera.py", line 141, in update
    self.extract_config_info(config)
  File "/usr/local/lib/python3.10/site-packages/blinkpy/camera.py", line 147, in extract_config_info
    self.name = config.get("name", "unknown")
AttributeError: 'NoneType' object has no attribute 'get'
2023-01-24 14:09:00.424 ERROR (MainThread) [homeassistant.components.automation.auto_trigger_camera] While executing automation automation.auto_trigger_camera
Traceback (most recent call last):
  File "/usr/src/homeassistant/homeassistant/components/automation/__init__.py", line 546, in async_trigger
    await self.action_script.async_run(
  File "/usr/src/homeassistant/homeassistant/helpers/script.py", line 1524, in async_run
    await asyncio.shield(run.async_run())
  File "/usr/src/homeassistant/homeassistant/helpers/script.py", line 409, in async_run
    await self._async_step(log_exceptions=False)
  File "/usr/src/homeassistant/homeassistant/helpers/script.py", line 453, in _async_step
    self._handle_exception(
  File "/usr/src/homeassistant/homeassistant/helpers/script.py", line 476, in _handle_exception
    raise exception
  File "/usr/src/homeassistant/homeassistant/helpers/script.py", line 451, in _async_step
    await getattr(self, handler)()
  File "/usr/src/homeassistant/homeassistant/helpers/script.py", line 684, in _async_call_service_step
    await service_task
  File "/usr/src/homeassistant/homeassistant/core.py", line 1755, in async_call
    task.result()
  File "/usr/src/homeassistant/homeassistant/core.py", line 1792, in _execute_service
    await cast(Callable[[ServiceCall], Awaitable[None]], handler.job.target)(
  File "/usr/src/homeassistant/homeassistant/helpers/entity_platform.py", line 787, in handle_service
    await service.entity_service_call(
  File "/usr/src/homeassistant/homeassistant/helpers/service.py", line 678, in entity_service_call
    future.result()  # pop exception if have
  File "/usr/src/homeassistant/homeassistant/helpers/entity.py", line 958, in async_request_call
    await coro
  File "/usr/src/homeassistant/homeassistant/helpers/service.py", line 715, in _handle_entity_call
    await result
  File "/usr/local/lib/python3.10/concurrent/futures/thread.py", line 58, in run
    result = self.fn(*self.args, **self.kwargs)
  File "/usr/src/homeassistant/homeassistant/components/blink/camera.py", line 84, in trigger_camera
    self.data.refresh()
  File "/usr/local/lib/python3.10/site-packages/blinkpy/helpers/util.py", line 144, in wrapper
    result = method(*args, *kwargs)
  File "/usr/local/lib/python3.10/site-packages/blinkpy/blinkpy.py", line 93, in refresh
    sync_module.refresh(force_cache=(force or force_cache))
  File "/usr/local/lib/python3.10/site-packages/blinkpy/sync_module.py", line 207, in refresh
    self.cameras[camera_name].update(camera_info, force_cache=force_cache)
  File "/usr/local/lib/python3.10/site-packages/blinkpy/camera.py", line 141, in update
    self.extract_config_info(config)
  File "/usr/local/lib/python3.10/site-packages/blinkpy/camera.py", line 147, in extract_config_info
    self.name = config.get("name", "unknown")
AttributeError: 'NoneType' object has no attribute 'get'
2023-01-24 14:09:00.433 ERROR (MainThread) [homeassistant.helpers.entity] Update for sensor.blink_garage_temperature fails
Traceback (most recent call last):
  File "/usr/src/homeassistant/homeassistant/helpers/entity.py", line 538, in async_update_ha_state
    await self.async_device_update()
  File "/usr/src/homeassistant/homeassistant/helpers/entity.py", line 736, in async_device_update
    raise exc
  File "/usr/local/lib/python3.10/concurrent/futures/thread.py", line 58, in run
    result = self.fn(*self.args, **self.kwargs)
  File "/usr/src/homeassistant/homeassistant/components/blink/sensor.py", line 77, in update
    self.data.refresh()
  File "/usr/local/lib/python3.10/site-packages/blinkpy/helpers/util.py", line 144, in wrapper
    result = method(*args, *kwargs)
  File "/usr/local/lib/python3.10/site-packages/blinkpy/blinkpy.py", line 93, in refresh
    sync_module.refresh(force_cache=(force or force_cache))
  File "/usr/local/lib/python3.10/site-packages/blinkpy/sync_module.py", line 207, in refresh
    self.cameras[camera_name].update(camera_info, force_cache=force_cache)
  File "/usr/local/lib/python3.10/site-packages/blinkpy/camera.py", line 141, in update
    self.extract_config_info(config)
  File "/usr/local/lib/python3.10/site-packages/blinkpy/camera.py", line 147, in extract_config_info
    self.name = config.get("name", "unknown")
AttributeError: 'NoneType' object has no attribute 'get'
2023-01-24 14:09:00.474 ERROR (MainThread) [homeassistant.helpers.entity] Update for binary_sensor.blink_garage_battery fails
Traceback (most recent call last):
  File "/usr/src/homeassistant/homeassistant/helpers/entity.py", line 538, in async_update_ha_state
    await self.async_device_update()
  File "/usr/src/homeassistant/homeassistant/helpers/entity.py", line 736, in async_device_update
    raise exc
  File "/usr/local/lib/python3.10/concurrent/futures/thread.py", line 58, in run
    result = self.fn(*self.args, **self.kwargs)
  File "/usr/src/homeassistant/homeassistant/components/blink/binary_sensor.py", line 74, in update
    self.data.refresh()
  File "/usr/local/lib/python3.10/site-packages/blinkpy/helpers/util.py", line 144, in wrapper
    result = method(*args, *kwargs)
  File "/usr/local/lib/python3.10/site-packages/blinkpy/blinkpy.py", line 93, in refresh
    sync_module.refresh(force_cache=(force or force_cache))
  File "/usr/local/lib/python3.10/site-packages/blinkpy/sync_module.py", line 207, in refresh
    self.cameras[camera_name].update(camera_info, force_cache=force_cache)
  File "/usr/local/lib/python3.10/site-packages/blinkpy/camera.py", line 141, in update
    self.extract_config_info(config)
  File "/usr/local/lib/python3.10/site-packages/blinkpy/camera.py", line 147, in extract_config_info
    self.name = config.get("name", "unknown")
AttributeError: 'NoneType' object has no attribute 'get'
2023-01-24 14:09:00.482 ERROR (MainThread) [homeassistant.helpers.entity] Update for alarm_control_panel.blink_garage fails
Traceback (most recent call last):
  File "/usr/src/homeassistant/homeassistant/helpers/entity.py", line 538, in async_update_ha_state
    await self.async_device_update()
  File "/usr/src/homeassistant/homeassistant/helpers/entity.py", line 736, in async_device_update
    raise exc
  File "/usr/local/lib/python3.10/concurrent/futures/thread.py", line 58, in run
    result = self.fn(*self.args, **self.kwargs)
  File "/usr/src/homeassistant/homeassistant/components/blink/alarm_control_panel.py", line 59, in update
    self.data.refresh()
  File "/usr/local/lib/python3.10/site-packages/blinkpy/helpers/util.py", line 144, in wrapper
    result = method(*args, *kwargs)
  File "/usr/local/lib/python3.10/site-packages/blinkpy/blinkpy.py", line 93, in refresh
    sync_module.refresh(force_cache=(force or force_cache))
  File "/usr/local/lib/python3.10/site-packages/blinkpy/sync_module.py", line 207, in refresh
    self.cameras[camera_name].update(camera_info, force_cache=force_cache)
  File "/usr/local/lib/python3.10/site-packages/blinkpy/camera.py", line 141, in update
    self.extract_config_info(config)
  File "/usr/local/lib/python3.10/site-packages/blinkpy/camera.py", line 147, in extract_config_info
    self.name = config.get("name", "unknown")
AttributeError: 'NoneType' object has no attribute 'get'
2023-01-24 14:09:00.493 ERROR (MainThread) [homeassistant.helpers.entity] Update for sensor.blink_garage_wifi_signal fails
Traceback (most recent call last):
  File "/usr/src/homeassistant/homeassistant/helpers/entity.py", line 538, in async_update_ha_state
    await self.async_device_update()
  File "/usr/src/homeassistant/homeassistant/helpers/entity.py", line 736, in async_device_update
    raise exc
  File "/usr/local/lib/python3.10/concurrent/futures/thread.py", line 58, in run
    result = self.fn(*self.args, **self.kwargs)
  File "/usr/src/homeassistant/homeassistant/components/blink/sensor.py", line 77, in update
    self.data.refresh()
  File "/usr/local/lib/python3.10/site-packages/blinkpy/helpers/util.py", line 144, in wrapper
    result = method(*args, *kwargs)
  File "/usr/local/lib/python3.10/site-packages/blinkpy/blinkpy.py", line 93, in refresh
    sync_module.refresh(force_cache=(force or force_cache))
  File "/usr/local/lib/python3.10/site-packages/blinkpy/sync_module.py", line 207, in refresh
    self.cameras[camera_name].update(camera_info, force_cache=force_cache)
  File "/usr/local/lib/python3.10/site-packages/blinkpy/camera.py", line 141, in update
    self.extract_config_info(config)
  File "/usr/local/lib/python3.10/site-packages/blinkpy/camera.py", line 147, in extract_config_info
    self.name = config.get("name", "unknown")
AttributeError: 'NoneType' object has no attribute 'get'
2023-01-24 14:09:00.540 ERROR (MainThread) [homeassistant.helpers.entity] Update for binary_sensor.blink_garage_camera_armed fails
Traceback (most recent call last):
  File "/usr/src/homeassistant/homeassistant/helpers/entity.py", line 538, in async_update_ha_state
    await self.async_device_update()
  File "/usr/src/homeassistant/homeassistant/helpers/entity.py", line 736, in async_device_update
    raise exc
  File "/usr/local/lib/python3.10/concurrent/futures/thread.py", line 58, in run
    result = self.fn(*self.args, **self.kwargs)
  File "/usr/src/homeassistant/homeassistant/components/blink/binary_sensor.py", line 74, in update
    self.data.refresh()
  File "/usr/local/lib/python3.10/site-packages/blinkpy/helpers/util.py", line 144, in wrapper
    result = method(*args, *kwargs)
  File "/usr/local/lib/python3.10/site-packages/blinkpy/blinkpy.py", line 93, in refresh
    sync_module.refresh(force_cache=(force or force_cache))
  File "/usr/local/lib/python3.10/site-packages/blinkpy/sync_module.py", line 207, in refresh
    self.cameras[camera_name].update(camera_info, force_cache=force_cache)
  File "/usr/local/lib/python3.10/site-packages/blinkpy/camera.py", line 141, in update
    self.extract_config_info(config)
  File "/usr/local/lib/python3.10/site-packages/blinkpy/camera.py", line 147, in extract_config_info
    self.name = config.get("name", "unknown")
AttributeError: 'NoneType' object has no attribute 'get'
2023-01-24 14:09:00.603 ERROR (MainThread) [homeassistant.helpers.entity] Update for binary_sensor.blink_garage_motion_detected fails
Traceback (most recent call last):
  File "/usr/src/homeassistant/homeassistant/helpers/entity.py", line 538, in async_update_ha_state
    await self.async_device_update()
  File "/usr/src/homeassistant/homeassistant/helpers/entity.py", line 736, in async_device_update
    raise exc
  File "/usr/local/lib/python3.10/concurrent/futures/thread.py", line 58, in run
    result = self.fn(*self.args, **self.kwargs)
  File "/usr/src/homeassistant/homeassistant/components/blink/binary_sensor.py", line 74, in update
    self.data.refresh()
  File "/usr/local/lib/python3.10/site-packages/blinkpy/helpers/util.py", line 144, in wrapper
    result = method(*args, *kwargs)
  File "/usr/local/lib/python3.10/site-packages/blinkpy/blinkpy.py", line 93, in refresh
    sync_module.refresh(force_cache=(force or force_cache))
  File "/usr/local/lib/python3.10/site-packages/blinkpy/sync_module.py", line 207, in refresh
    self.cameras[camera_name].update(camera_info, force_cache=force_cache)
  File "/usr/local/lib/python3.10/site-packages/blinkpy/camera.py", line 141, in update
    self.extract_config_info(config)
  File "/usr/local/lib/python3.10/site-packages/blinkpy/camera.py", line 147, in extract_config_info
    self.name = config.get("name", "unknown")
AttributeError: 'NoneType' object has no attribute 'get'
2023-01-24 14:10:00.430 ERROR (MainThread) [homeassistant.components.automation.auto_trigger_camera] Auto Trigger Camera: Error executing script. Unexpected error for call_service at pos 1: 'NoneType' object has no attribute 'get'
Traceback (most recent call last):
  File "/usr/src/homeassistant/homeassistant/helpers/script.py", line 451, in _async_step
    await getattr(self, handler)()
  File "/usr/src/homeassistant/homeassistant/helpers/script.py", line 684, in _async_call_service_step
    await service_task
  File "/usr/src/homeassistant/homeassistant/core.py", line 1755, in async_call
    task.result()
  File "/usr/src/homeassistant/homeassistant/core.py", line 1792, in _execute_service
    await cast(Callable[[ServiceCall], Awaitable[None]], handler.job.target)(
  File "/usr/src/homeassistant/homeassistant/helpers/entity_platform.py", line 787, in handle_service
    await service.entity_service_call(
  File "/usr/src/homeassistant/homeassistant/helpers/service.py", line 678, in entity_service_call
    future.result()  # pop exception if have
  File "/usr/src/homeassistant/homeassistant/helpers/entity.py", line 958, in async_request_call
    await coro
  File "/usr/src/homeassistant/homeassistant/helpers/service.py", line 715, in _handle_entity_call
    await result
  File "/usr/local/lib/python3.10/concurrent/futures/thread.py", line 58, in run
    result = self.fn(*self.args, **self.kwargs)
  File "/usr/src/homeassistant/homeassistant/components/blink/camera.py", line 84, in trigger_camera
    self.data.refresh()
  File "/usr/local/lib/python3.10/site-packages/blinkpy/helpers/util.py", line 144, in wrapper
    result = method(*args, *kwargs)
  File "/usr/local/lib/python3.10/site-packages/blinkpy/blinkpy.py", line 93, in refresh
    sync_module.refresh(force_cache=(force or force_cache))
  File "/usr/local/lib/python3.10/site-packages/blinkpy/sync_module.py", line 207, in refresh
    self.cameras[camera_name].update(camera_info, force_cache=force_cache)
  File "/usr/local/lib/python3.10/site-packages/blinkpy/camera.py", line 141, in update
    self.extract_config_info(config)
  File "/usr/local/lib/python3.10/site-packages/blinkpy/camera.py", line 147, in extract_config_info
    self.name = config.get("name", "unknown")
AttributeError: 'NoneType' object has no attribute 'get'
2023-01-24 14:10:00.431 ERROR (MainThread) [homeassistant.components.automation.auto_trigger_camera] While executing automation automation.auto_trigger_camera
Traceback (most recent call last):
  File "/usr/src/homeassistant/homeassistant/components/automation/__init__.py", line 546, in async_trigger
    await self.action_script.async_run(
  File "/usr/src/homeassistant/homeassistant/helpers/script.py", line 1524, in async_run
    await asyncio.shield(run.async_run())
  File "/usr/src/homeassistant/homeassistant/helpers/script.py", line 409, in async_run
    await self._async_step(log_exceptions=False)
  File "/usr/src/homeassistant/homeassistant/helpers/script.py", line 453, in _async_step
    self._handle_exception(
  File "/usr/src/homeassistant/homeassistant/helpers/script.py", line 476, in _handle_exception
    raise exception
  File "/usr/src/homeassistant/homeassistant/helpers/script.py", line 451, in _async_step
    await getattr(self, handler)()
  File "/usr/src/homeassistant/homeassistant/helpers/script.py", line 684, in _async_call_service_step
    await service_task
  File "/usr/src/homeassistant/homeassistant/core.py", line 1755, in async_call
    task.result()
  File "/usr/src/homeassistant/homeassistant/core.py", line 1792, in _execute_service
    await cast(Callable[[ServiceCall], Awaitable[None]], handler.job.target)(
  File "/usr/src/homeassistant/homeassistant/helpers/entity_platform.py", line 787, in handle_service
    await service.entity_service_call(
  File "/usr/src/homeassistant/homeassistant/helpers/service.py", line 678, in entity_service_call
    future.result()  # pop exception if have
  File "/usr/src/homeassistant/homeassistant/helpers/entity.py", line 958, in async_request_call
    await coro
  File "/usr/src/homeassistant/homeassistant/helpers/service.py", line 715, in _handle_entity_call
    await result
  File "/usr/local/lib/python3.10/concurrent/futures/thread.py", line 58, in run
    result = self.fn(*self.args, **self.kwargs)
  File "/usr/src/homeassistant/homeassistant/components/blink/camera.py", line 84, in trigger_camera
    self.data.refresh()
  File "/usr/local/lib/python3.10/site-packages/blinkpy/helpers/util.py", line 144, in wrapper
    result = method(*args, *kwargs)
  File "/usr/local/lib/python3.10/site-packages/blinkpy/blinkpy.py", line 93, in refresh
    sync_module.refresh(force_cache=(force or force_cache))
  File "/usr/local/lib/python3.10/site-packages/blinkpy/sync_module.py", line 207, in refresh
    self.cameras[camera_name].update(camera_info, force_cache=force_cache)
  File "/usr/local/lib/python3.10/site-packages/blinkpy/camera.py", line 141, in update
    self.extract_config_info(config)
  File "/usr/local/lib/python3.10/site-packages/blinkpy/camera.py", line 147, in extract_config_info
    self.name = config.get("name", "unknown")
AttributeError: 'NoneType' object has no attribute 'get'
2023-01-24 14:10:00.442 ERROR (MainThread) [homeassistant.helpers.entity] Update for sensor.blink_garage_temperature fails
Traceback (most recent call last):
  File "/usr/src/homeassistant/homeassistant/helpers/entity.py", line 538, in async_update_ha_state
    await self.async_device_update()
  File "/usr/src/homeassistant/homeassistant/helpers/entity.py", line 736, in async_device_update
    raise exc
  File "/usr/local/lib/python3.10/concurrent/futures/thread.py", line 58, in run
    result = self.fn(*self.args, **self.kwargs)
  File "/usr/src/homeassistant/homeassistant/components/blink/sensor.py", line 77, in update
    self.data.refresh()
  File "/usr/local/lib/python3.10/site-packages/blinkpy/helpers/util.py", line 144, in wrapper
    result = method(*args, *kwargs)
  File "/usr/local/lib/python3.10/site-packages/blinkpy/blinkpy.py", line 93, in refresh
    sync_module.refresh(force_cache=(force or force_cache))
  File "/usr/local/lib/python3.10/site-packages/blinkpy/sync_module.py", line 207, in refresh
    self.cameras[camera_name].update(camera_info, force_cache=force_cache)
  File "/usr/local/lib/python3.10/site-packages/blinkpy/camera.py", line 141, in update
    self.extract_config_info(config)
  File "/usr/local/lib/python3.10/site-packages/blinkpy/camera.py", line 147, in extract_config_info
    self.name = config.get("name", "unknown")
AttributeError: 'NoneType' object has no attribute 'get'
2023-01-24 14:10:00.460 ERROR (MainThread) [homeassistant.helpers.entity] Update for alarm_control_panel.blink_garage fails
Traceback (most recent call last):
  File "/usr/src/homeassistant/homeassistant/helpers/entity.py", line 538, in async_update_ha_state
    await self.async_device_update()
  File "/usr/src/homeassistant/homeassistant/helpers/entity.py", line 736, in async_device_update
    raise exc
  File "/usr/local/lib/python3.10/concurrent/futures/thread.py", line 58, in run
    result = self.fn(*self.args, **self.kwargs)
  File "/usr/src/homeassistant/homeassistant/components/blink/alarm_control_panel.py", line 59, in update
    self.data.refresh()
  File "/usr/local/lib/python3.10/site-packages/blinkpy/helpers/util.py", line 144, in wrapper
    result = method(*args, *kwargs)
  File "/usr/local/lib/python3.10/site-packages/blinkpy/blinkpy.py", line 93, in refresh
    sync_module.refresh(force_cache=(force or force_cache))
  File "/usr/local/lib/python3.10/site-packages/blinkpy/sync_module.py", line 207, in refresh
    self.cameras[camera_name].update(camera_info, force_cache=force_cache)
  File "/usr/local/lib/python3.10/site-packages/blinkpy/camera.py", line 141, in update
    self.extract_config_info(config)
  File "/usr/local/lib/python3.10/site-packages/blinkpy/camera.py", line 147, in extract_config_info
    self.name = config.get("name", "unknown")
AttributeError: 'NoneType' object has no attribute 'get'
2023-01-24 14:10:00.470 ERROR (MainThread) [homeassistant.helpers.entity] Update for binary_sensor.blink_garage_battery fails
Traceback (most recent call last):
  File "/usr/src/homeassistant/homeassistant/helpers/entity.py", line 538, in async_update_ha_state
    await self.async_device_update()
  File "/usr/src/homeassistant/homeassistant/helpers/entity.py", line 736, in async_device_update
    raise exc
  File "/usr/local/lib/python3.10/concurrent/futures/thread.py", line 58, in run
    result = self.fn(*self.args, **self.kwargs)
  File "/usr/src/homeassistant/homeassistant/components/blink/binary_sensor.py", line 74, in update
    self.data.refresh()
  File "/usr/local/lib/python3.10/site-packages/blinkpy/helpers/util.py", line 144, in wrapper
    result = method(*args, *kwargs)
  File "/usr/local/lib/python3.10/site-packages/blinkpy/blinkpy.py", line 93, in refresh
    sync_module.refresh(force_cache=(force or force_cache))
  File "/usr/local/lib/python3.10/site-packages/blinkpy/sync_module.py", line 207, in refresh
    self.cameras[camera_name].update(camera_info, force_cache=force_cache)
  File "/usr/local/lib/python3.10/site-packages/blinkpy/camera.py", line 141, in update
    self.extract_config_info(config)
  File "/usr/local/lib/python3.10/site-packages/blinkpy/camera.py", line 147, in extract_config_info
    self.name = config.get("name", "unknown")
AttributeError: 'NoneType' object has no attribute 'get'
2023-01-24 14:10:00.494 ERROR (MainThread) [homeassistant.helpers.entity] Update for sensor.blink_garage_wifi_signal fails
Traceback (most recent call last):
  File "/usr/src/homeassistant/homeassistant/helpers/entity.py", line 538, in async_update_ha_state
    await self.async_device_update()
  File "/usr/src/homeassistant/homeassistant/helpers/entity.py", line 736, in async_device_update
    raise exc
  File "/usr/local/lib/python3.10/concurrent/futures/thread.py", line 58, in run
    result = self.fn(*self.args, **self.kwargs)
  File "/usr/src/homeassistant/homeassistant/components/blink/sensor.py", line 77, in update
    self.data.refresh()
  File "/usr/local/lib/python3.10/site-packages/blinkpy/helpers/util.py", line 144, in wrapper
    result = method(*args, *kwargs)
  File "/usr/local/lib/python3.10/site-packages/blinkpy/blinkpy.py", line 93, in refresh
    sync_module.refresh(force_cache=(force or force_cache))
  File "/usr/local/lib/python3.10/site-packages/blinkpy/sync_module.py", line 207, in refresh
    self.cameras[camera_name].update(camera_info, force_cache=force_cache)
  File "/usr/local/lib/python3.10/site-packages/blinkpy/camera.py", line 141, in update
    self.extract_config_info(config)
  File "/usr/local/lib/python3.10/site-packages/blinkpy/camera.py", line 147, in extract_config_info
    self.name = config.get("name", "unknown")
AttributeError: 'NoneType' object has no attribute 'get'
2023-01-24 14:10:00.529 ERROR (MainThread) [homeassistant.helpers.entity] Update for binary_sensor.blink_garage_camera_armed fails
Traceback (most recent call last):
  File "/usr/src/homeassistant/homeassistant/helpers/entity.py", line 538, in async_update_ha_state
    await self.async_device_update()
  File "/usr/src/homeassistant/homeassistant/helpers/entity.py", line 736, in async_device_update
    raise exc
  File "/usr/local/lib/python3.10/concurrent/futures/thread.py", line 58, in run
    result = self.fn(*self.args, **self.kwargs)
  File "/usr/src/homeassistant/homeassistant/components/blink/binary_sensor.py", line 74, in update
    self.data.refresh()
  File "/usr/local/lib/python3.10/site-packages/blinkpy/helpers/util.py", line 144, in wrapper
    result = method(*args, *kwargs)
  File "/usr/local/lib/python3.10/site-packages/blinkpy/blinkpy.py", line 93, in refresh
    sync_module.refresh(force_cache=(force or force_cache))
  File "/usr/local/lib/python3.10/site-packages/blinkpy/sync_module.py", line 207, in refresh
    self.cameras[camera_name].update(camera_info, force_cache=force_cache)
  File "/usr/local/lib/python3.10/site-packages/blinkpy/camera.py", line 141, in update
    self.extract_config_info(config)
  File "/usr/local/lib/python3.10/site-packages/blinkpy/camera.py", line 147, in extract_config_info
    self.name = config.get("name", "unknown")
AttributeError: 'NoneType' object has no attribute 'get'
2023-01-24 14:10:00.588 ERROR (MainThread) [homeassistant.helpers.entity] Update for binary_sensor.blink_garage_motion_detected fails
Traceback (most recent call last):
  File "/usr/src/homeassistant/homeassistant/helpers/entity.py", line 538, in async_update_ha_state
    await self.async_device_update()
  File "/usr/src/homeassistant/homeassistant/helpers/entity.py", line 736, in async_device_update
    raise exc
  File "/usr/local/lib/python3.10/concurrent/futures/thread.py", line 58, in run
    result = self.fn(*self.args, **self.kwargs)
  File "/usr/src/homeassistant/homeassistant/components/blink/binary_sensor.py", line 74, in update
    self.data.refresh()
  File "/usr/local/lib/python3.10/site-packages/blinkpy/helpers/util.py", line 144, in wrapper
    result = method(*args, *kwargs)
  File "/usr/local/lib/python3.10/site-packages/blinkpy/blinkpy.py", line 93, in refresh
    sync_module.refresh(force_cache=(force or force_cache))
  File "/usr/local/lib/python3.10/site-packages/blinkpy/sync_module.py", line 207, in refresh
    self.cameras[camera_name].update(camera_info, force_cache=force_cache)
  File "/usr/local/lib/python3.10/site-packages/blinkpy/camera.py", line 141, in update
    self.extract_config_info(config)
  File "/usr/local/lib/python3.10/site-packages/blinkpy/camera.py", line 147, in extract_config_info
    self.name = config.get("name", "unknown")
AttributeError: 'NoneType' object has no attribute 'get'
2023-01-24 14:11:00.436 ERROR (MainThread) [homeassistant.components.automation.auto_trigger_camera] Auto Trigger Camera: Error executing script. Unexpected error for call_service at pos 1: 'NoneType' object has no attribute 'get'
Traceback (most recent call last):
  File "/usr/src/homeassistant/homeassistant/helpers/script.py", line 451, in _async_step
    await getattr(self, handler)()
  File "/usr/src/homeassistant/homeassistant/helpers/script.py", line 684, in _async_call_service_step
    await service_task
  File "/usr/src/homeassistant/homeassistant/core.py", line 1755, in async_call
    task.result()
  File "/usr/src/homeassistant/homeassistant/core.py", line 1792, in _execute_service
    await cast(Callable[[ServiceCall], Awaitable[None]], handler.job.target)(
  File "/usr/src/homeassistant/homeassistant/helpers/entity_platform.py", line 787, in handle_service
    await service.entity_service_call(
  File "/usr/src/homeassistant/homeassistant/helpers/service.py", line 678, in entity_service_call
    future.result()  # pop exception if have
  File "/usr/src/homeassistant/homeassistant/helpers/entity.py", line 958, in async_request_call
    await coro
  File "/usr/src/homeassistant/homeassistant/helpers/service.py", line 715, in _handle_entity_call
    await result
  File "/usr/local/lib/python3.10/concurrent/futures/thread.py", line 58, in run
    result = self.fn(*self.args, **self.kwargs)
  File "/usr/src/homeassistant/homeassistant/components/blink/camera.py", line 84, in trigger_camera
    self.data.refresh()
  File "/usr/local/lib/python3.10/site-packages/blinkpy/helpers/util.py", line 144, in wrapper
    result = method(*args, *kwargs)
  File "/usr/local/lib/python3.10/site-packages/blinkpy/blinkpy.py", line 93, in refresh
    sync_module.refresh(force_cache=(force or force_cache))
  File "/usr/local/lib/python3.10/site-packages/blinkpy/sync_module.py", line 207, in refresh
    self.cameras[camera_name].update(camera_info, force_cache=force_cache)
  File "/usr/local/lib/python3.10/site-packages/blinkpy/camera.py", line 141, in update
    self.extract_config_info(config)
  File "/usr/local/lib/python3.10/site-packages/blinkpy/camera.py", line 147, in extract_config_info
    self.name = config.get("name", "unknown")
AttributeError: 'NoneType' object has no attribute 'get'
2023-01-24 14:11:00.437 ERROR (MainThread) [homeassistant.components.automation.auto_trigger_camera] While executing automation automation.auto_trigger_camera
Traceback (most recent call last):
  File "/usr/src/homeassistant/homeassistant/components/automation/__init__.py", line 546, in async_trigger
    await self.action_script.async_run(
  File "/usr/src/homeassistant/homeassistant/helpers/script.py", line 1524, in async_run
    await asyncio.shield(run.async_run())
  File "/usr/src/homeassistant/homeassistant/helpers/script.py", line 409, in async_run
    await self._async_step(log_exceptions=False)
  File "/usr/src/homeassistant/homeassistant/helpers/script.py", line 453, in _async_step
    self._handle_exception(
  File "/usr/src/homeassistant/homeassistant/helpers/script.py", line 476, in _handle_exception
    raise exception
  File "/usr/src/homeassistant/homeassistant/helpers/script.py", line 451, in _async_step
    await getattr(self, handler)()
  File "/usr/src/homeassistant/homeassistant/helpers/script.py", line 684, in _async_call_service_step
    await service_task
  File "/usr/src/homeassistant/homeassistant/core.py", line 1755, in async_call
    task.result()
  File "/usr/src/homeassistant/homeassistant/core.py", line 1792, in _execute_service
    await cast(Callable[[ServiceCall], Awaitable[None]], handler.job.target)(
  File "/usr/src/homeassistant/homeassistant/helpers/entity_platform.py", line 787, in handle_service
    await service.entity_service_call(
  File "/usr/src/homeassistant/homeassistant/helpers/service.py", line 678, in entity_service_call
    future.result()  # pop exception if have
  File "/usr/src/homeassistant/homeassistant/helpers/entity.py", line 958, in async_request_call
    await coro
  File "/usr/src/homeassistant/homeassistant/helpers/service.py", line 715, in _handle_entity_call
    await result
  File "/usr/local/lib/python3.10/concurrent/futures/thread.py", line 58, in run
    result = self.fn(*self.args, **self.kwargs)
  File "/usr/src/homeassistant/homeassistant/components/blink/camera.py", line 84, in trigger_camera
    self.data.refresh()
  File "/usr/local/lib/python3.10/site-packages/blinkpy/helpers/util.py", line 144, in wrapper
    result = method(*args, *kwargs)
  File "/usr/local/lib/python3.10/site-packages/blinkpy/blinkpy.py", line 93, in refresh
    sync_module.refresh(force_cache=(force or force_cache))
  File "/usr/local/lib/python3.10/site-packages/blinkpy/sync_module.py", line 207, in refresh
    self.cameras[camera_name].update(camera_info, force_cache=force_cache)
  File "/usr/local/lib/python3.10/site-packages/blinkpy/camera.py", line 141, in update
    self.extract_config_info(config)
  File "/usr/local/lib/python3.10/site-packages/blinkpy/camera.py", line 147, in extract_config_info
    self.name = config.get("name", "unknown")
AttributeError: 'NoneType' object has no attribute 'get'
2023-01-24 14:11:00.439 ERROR (MainThread) [homeassistant.helpers.entity] Update for sensor.blink_garage_temperature fails
Traceback (most recent call last):
  File "/usr/src/homeassistant/homeassistant/helpers/entity.py", line 538, in async_update_ha_state
    await self.async_device_update()
  File "/usr/src/homeassistant/homeassistant/helpers/entity.py", line 736, in async_device_update
    raise exc
  File "/usr/local/lib/python3.10/concurrent/futures/thread.py", line 58, in run
    result = self.fn(*self.args, **self.kwargs)
  File "/usr/src/homeassistant/homeassistant/components/blink/sensor.py", line 77, in update
    self.data.refresh()
  File "/usr/local/lib/python3.10/site-packages/blinkpy/helpers/util.py", line 144, in wrapper
    result = method(*args, *kwargs)
  File "/usr/local/lib/python3.10/site-packages/blinkpy/blinkpy.py", line 93, in refresh
    sync_module.refresh(force_cache=(force or force_cache))
  File "/usr/local/lib/python3.10/site-packages/blinkpy/sync_module.py", line 207, in refresh
    self.cameras[camera_name].update(camera_info, force_cache=force_cache)
  File "/usr/local/lib/python3.10/site-packages/blinkpy/camera.py", line 141, in update
    self.extract_config_info(config)
  File "/usr/local/lib/python3.10/site-packages/blinkpy/camera.py", line 147, in extract_config_info
    self.name = config.get("name", "unknown")
AttributeError: 'NoneType' object has no attribute 'get'
2023-01-24 14:11:00.478 ERROR (MainThread) [homeassistant.helpers.entity] Update for alarm_control_panel.blink_garage fails
Traceback (most recent call last):
  File "/usr/src/homeassistant/homeassistant/helpers/entity.py", line 538, in async_update_ha_state
    await self.async_device_update()
  File "/usr/src/homeassistant/homeassistant/helpers/entity.py", line 736, in async_device_update
    raise exc
  File "/usr/local/lib/python3.10/concurrent/futures/thread.py", line 58, in run
    result = self.fn(*self.args, **self.kwargs)
  File "/usr/src/homeassistant/homeassistant/components/blink/alarm_control_panel.py", line 59, in update
    self.data.refresh()
  File "/usr/local/lib/python3.10/site-packages/blinkpy/helpers/util.py", line 144, in wrapper
    result = method(*args, *kwargs)
  File "/usr/local/lib/python3.10/site-packages/blinkpy/blinkpy.py", line 93, in refresh
    sync_module.refresh(force_cache=(force or force_cache))
  File "/usr/local/lib/python3.10/site-packages/blinkpy/sync_module.py", line 207, in refresh
    self.cameras[camera_name].update(camera_info, force_cache=force_cache)
  File "/usr/local/lib/python3.10/site-packages/blinkpy/camera.py", line 141, in update
    self.extract_config_info(config)
  File "/usr/local/lib/python3.10/site-packages/blinkpy/camera.py", line 147, in extract_config_info
    self.name = config.get("name", "unknown")
AttributeError: 'NoneType' object has no attribute 'get'
2023-01-24 14:11:00.491 ERROR (MainThread) [homeassistant.helpers.entity] Update for sensor.blink_garage_wifi_signal fails
Traceback (most recent call last):
  File "/usr/src/homeassistant/homeassistant/helpers/entity.py", line 538, in async_update_ha_state
    await self.async_device_update()
  File "/usr/src/homeassistant/homeassistant/helpers/entity.py", line 736, in async_device_update
    raise exc
  File "/usr/local/lib/python3.10/concurrent/futures/thread.py", line 58, in run
    result = self.fn(*self.args, **self.kwargs)
  File "/usr/src/homeassistant/homeassistant/components/blink/sensor.py", line 77, in update
    self.data.refresh()
  File "/usr/local/lib/python3.10/site-packages/blinkpy/helpers/util.py", line 144, in wrapper
    result = method(*args, *kwargs)
  File "/usr/local/lib/python3.10/site-packages/blinkpy/blinkpy.py", line 93, in refresh
    sync_module.refresh(force_cache=(force or force_cache))
  File "/usr/local/lib/python3.10/site-packages/blinkpy/sync_module.py", line 207, in refresh
    self.cameras[camera_name].update(camera_info, force_cache=force_cache)
  File "/usr/local/lib/python3.10/site-packages/blinkpy/camera.py", line 141, in update
    self.extract_config_info(config)
  File "/usr/local/lib/python3.10/site-packages/blinkpy/camera.py", line 147, in extract_config_info
    self.name = config.get("name", "unknown")
AttributeError: 'NoneType' object has no attribute 'get'
2023-01-24 14:11:00.493 ERROR (MainThread) [homeassistant.helpers.entity] Update for binary_sensor.blink_garage_battery fails
Traceback (most recent call last):
  File "/usr/src/homeassistant/homeassistant/helpers/entity.py", line 538, in async_update_ha_state
    await self.async_device_update()
  File "/usr/src/homeassistant/homeassistant/helpers/entity.py", line 736, in async_device_update
    raise exc
  File "/usr/local/lib/python3.10/concurrent/futures/thread.py", line 58, in run
    result = self.fn(*self.args, **self.kwargs)
  File "/usr/src/homeassistant/homeassistant/components/blink/binary_sensor.py", line 74, in update
    self.data.refresh()
  File "/usr/local/lib/python3.10/site-packages/blinkpy/helpers/util.py", line 144, in wrapper
    result = method(*args, *kwargs)
  File "/usr/local/lib/python3.10/site-packages/blinkpy/blinkpy.py", line 93, in refresh
    sync_module.refresh(force_cache=(force or force_cache))
  File "/usr/local/lib/python3.10/site-packages/blinkpy/sync_module.py", line 207, in refresh
    self.cameras[camera_name].update(camera_info, force_cache=force_cache)
  File "/usr/local/lib/python3.10/site-packages/blinkpy/camera.py", line 141, in update
    self.extract_config_info(config)
  File "/usr/local/lib/python3.10/site-packages/blinkpy/camera.py", line 147, in extract_config_info
    self.name = config.get("name", "unknown")
AttributeError: 'NoneType' object has no attribute 'get'
2023-01-24 14:11:00.553 ERROR (MainThread) [homeassistant.helpers.entity] Update for binary_sensor.blink_garage_camera_armed fails
Traceback (most recent call last):
  File "/usr/src/homeassistant/homeassistant/helpers/entity.py", line 538, in async_update_ha_state
    await self.async_device_update()
  File "/usr/src/homeassistant/homeassistant/helpers/entity.py", line 736, in async_device_update
    raise exc
  File "/usr/local/lib/python3.10/concurrent/futures/thread.py", line 58, in run
    result = self.fn(*self.args, **self.kwargs)
  File "/usr/src/homeassistant/homeassistant/components/blink/binary_sensor.py", line 74, in update
    self.data.refresh()
  File "/usr/local/lib/python3.10/site-packages/blinkpy/helpers/util.py", line 144, in wrapper
    result = method(*args, *kwargs)
  File "/usr/local/lib/python3.10/site-packages/blinkpy/blinkpy.py", line 93, in refresh
    sync_module.refresh(force_cache=(force or force_cache))
  File "/usr/local/lib/python3.10/site-packages/blinkpy/sync_module.py", line 207, in refresh
    self.cameras[camera_name].update(camera_info, force_cache=force_cache)
  File "/usr/local/lib/python3.10/site-packages/blinkpy/camera.py", line 141, in update
    self.extract_config_info(config)
  File "/usr/local/lib/python3.10/site-packages/blinkpy/camera.py", line 147, in extract_config_info
    self.name = config.get("name", "unknown")
AttributeError: 'NoneType' object has no attribute 'get'
2023-01-24 14:11:00.614 ERROR (MainThread) [homeassistant.helpers.entity] Update for binary_sensor.blink_garage_motion_detected fails
Traceback (most recent call last):
  File "/usr/src/homeassistant/homeassistant/helpers/entity.py", line 538, in async_update_ha_state
    await self.async_device_update()
  File "/usr/src/homeassistant/homeassistant/helpers/entity.py", line 736, in async_device_update
    raise exc
  File "/usr/local/lib/python3.10/concurrent/futures/thread.py", line 58, in run
    result = self.fn(*self.args, **self.kwargs)
  File "/usr/src/homeassistant/homeassistant/components/blink/binary_sensor.py", line 74, in update
    self.data.refresh()
  File "/usr/local/lib/python3.10/site-packages/blinkpy/helpers/util.py", line 144, in wrapper
    result = method(*args, *kwargs)
  File "/usr/local/lib/python3.10/site-packages/blinkpy/blinkpy.py", line 93, in refresh
    sync_module.refresh(force_cache=(force or force_cache))
  File "/usr/local/lib/python3.10/site-packages/blinkpy/sync_module.py", line 207, in refresh
    self.cameras[camera_name].update(camera_info, force_cache=force_cache)
  File "/usr/local/lib/python3.10/site-packages/blinkpy/camera.py", line 141, in update
    self.extract_config_info(config)
  File "/usr/local/lib/python3.10/site-packages/blinkpy/camera.py", line 147, in extract_config_info
    self.name = config.get("name", "unknown")
AttributeError: 'NoneType' object has no attribute 'get'
2023-01-24 14:13:00.426 ERROR (MainThread) [homeassistant.components.automation.auto_trigger_camera] Auto Trigger Camera: Error executing script. Unexpected error for call_service at pos 1: 'NoneType' object has no attribute 'get'
Traceback (most recent call last):
  File "/usr/src/homeassistant/homeassistant/helpers/script.py", line 451, in _async_step
    await getattr(self, handler)()
  File "/usr/src/homeassistant/homeassistant/helpers/script.py", line 684, in _async_call_service_step
    await service_task
  File "/usr/src/homeassistant/homeassistant/core.py", line 1755, in async_call
    task.result()
  File "/usr/src/homeassistant/homeassistant/core.py", line 1792, in _execute_service
    await cast(Callable[[ServiceCall], Awaitable[None]], handler.job.target)(
  File "/usr/src/homeassistant/homeassistant/helpers/entity_platform.py", line 787, in handle_service
    await service.entity_service_call(
  File "/usr/src/homeassistant/homeassistant/helpers/service.py", line 678, in entity_service_call
    future.result()  # pop exception if have
  File "/usr/src/homeassistant/homeassistant/helpers/entity.py", line 958, in async_request_call
    await coro
  File "/usr/src/homeassistant/homeassistant/helpers/service.py", line 715, in _handle_entity_call
    await result
  File "/usr/local/lib/python3.10/concurrent/futures/thread.py", line 58, in run
    result = self.fn(*self.args, **self.kwargs)
  File "/usr/src/homeassistant/homeassistant/components/blink/camera.py", line 84, in trigger_camera
    self.data.refresh()
  File "/usr/local/lib/python3.10/site-packages/blinkpy/helpers/util.py", line 144, in wrapper
    result = method(*args, *kwargs)
  File "/usr/local/lib/python3.10/site-packages/blinkpy/blinkpy.py", line 93, in refresh
    sync_module.refresh(force_cache=(force or force_cache))
  File "/usr/local/lib/python3.10/site-packages/blinkpy/sync_module.py", line 207, in refresh
    self.cameras[camera_name].update(camera_info, force_cache=force_cache)
  File "/usr/local/lib/python3.10/site-packages/blinkpy/camera.py", line 141, in update
    self.extract_config_info(config)
  File "/usr/local/lib/python3.10/site-packages/blinkpy/camera.py", line 147, in extract_config_info
    self.name = config.get("name", "unknown")
AttributeError: 'NoneType' object has no attribute 'get'
2023-01-24 14:13:00.430 ERROR (MainThread) [homeassistant.components.automation.auto_trigger_camera] While executing automation automation.auto_trigger_camera
Traceback (most recent call last):
  File "/usr/src/homeassistant/homeassistant/components/automation/__init__.py", line 546, in async_trigger
    await self.action_script.async_run(
  File "/usr/src/homeassistant/homeassistant/helpers/script.py", line 1524, in async_run
    await asyncio.shield(run.async_run())
  File "/usr/src/homeassistant/homeassistant/helpers/script.py", line 409, in async_run
    await self._async_step(log_exceptions=False)
  File "/usr/src/homeassistant/homeassistant/helpers/script.py", line 453, in _async_step
    self._handle_exception(
  File "/usr/src/homeassistant/homeassistant/helpers/script.py", line 476, in _handle_exception
    raise exception
  File "/usr/src/homeassistant/homeassistant/helpers/script.py", line 451, in _async_step
    await getattr(self, handler)()
  File "/usr/src/homeassistant/homeassistant/helpers/script.py", line 684, in _async_call_service_step
    await service_task
  File "/usr/src/homeassistant/homeassistant/core.py", line 1755, in async_call
    task.result()
  File "/usr/src/homeassistant/homeassistant/core.py", line 1792, in _execute_service
    await cast(Callable[[ServiceCall], Awaitable[None]], handler.job.target)(
  File "/usr/src/homeassistant/homeassistant/helpers/entity_platform.py", line 787, in handle_service
    await service.entity_service_call(
  File "/usr/src/homeassistant/homeassistant/helpers/service.py", line 678, in entity_service_call
    future.result()  # pop exception if have
  File "/usr/src/homeassistant/homeassistant/helpers/entity.py", line 958, in async_request_call
    await coro
  File "/usr/src/homeassistant/homeassistant/helpers/service.py", line 715, in _handle_entity_call
    await result
  File "/usr/local/lib/python3.10/concurrent/futures/thread.py", line 58, in run
    result = self.fn(*self.args, **self.kwargs)
  File "/usr/src/homeassistant/homeassistant/components/blink/camera.py", line 84, in trigger_camera
    self.data.refresh()
  File "/usr/local/lib/python3.10/site-packages/blinkpy/helpers/util.py", line 144, in wrapper
    result = method(*args, *kwargs)
  File "/usr/local/lib/python3.10/site-packages/blinkpy/blinkpy.py", line 93, in refresh
    sync_module.refresh(force_cache=(force or force_cache))
  File "/usr/local/lib/python3.10/site-packages/blinkpy/sync_module.py", line 207, in refresh
    self.cameras[camera_name].update(camera_info, force_cache=force_cache)
  File "/usr/local/lib/python3.10/site-packages/blinkpy/camera.py", line 141, in update
    self.extract_config_info(config)
  File "/usr/local/lib/python3.10/site-packages/blinkpy/camera.py", line 147, in extract_config_info
    self.name = config.get("name", "unknown")
AttributeError: 'NoneType' object has no attribute 'get'
2023-01-24 14:13:00.495 ERROR (MainThread) [homeassistant.helpers.entity] Update for alarm_control_panel.blink_garage fails
Traceback (most recent call last):
  File "/usr/src/homeassistant/homeassistant/helpers/entity.py", line 538, in async_update_ha_state
    await self.async_device_update()
  File "/usr/src/homeassistant/homeassistant/helpers/entity.py", line 736, in async_device_update
    raise exc
  File "/usr/local/lib/python3.10/concurrent/futures/thread.py", line 58, in run
    result = self.fn(*self.args, **self.kwargs)
  File "/usr/src/homeassistant/homeassistant/components/blink/alarm_control_panel.py", line 59, in update
    self.data.refresh()
  File "/usr/local/lib/python3.10/site-packages/blinkpy/helpers/util.py", line 144, in wrapper
    result = method(*args, *kwargs)
  File "/usr/local/lib/python3.10/site-packages/blinkpy/blinkpy.py", line 93, in refresh
    sync_module.refresh(force_cache=(force or force_cache))
  File "/usr/local/lib/python3.10/site-packages/blinkpy/sync_module.py", line 207, in refresh
    self.cameras[camera_name].update(camera_info, force_cache=force_cache)
  File "/usr/local/lib/python3.10/site-packages/blinkpy/camera.py", line 141, in update
    self.extract_config_info(config)
  File "/usr/local/lib/python3.10/site-packages/blinkpy/camera.py", line 147, in extract_config_info
    self.name = config.get("name", "unknown")
AttributeError: 'NoneType' object has no attribute 'get'
2023-01-24 14:13:00.498 ERROR (MainThread) [homeassistant.helpers.entity] Update for binary_sensor.blink_garage_battery fails
Traceback (most recent call last):
  File "/usr/src/homeassistant/homeassistant/helpers/entity.py", line 538, in async_update_ha_state
    await self.async_device_update()
  File "/usr/src/homeassistant/homeassistant/helpers/entity.py", line 736, in async_device_update
    raise exc
  File "/usr/local/lib/python3.10/concurrent/futures/thread.py", line 58, in run
    result = self.fn(*self.args, **self.kwargs)
  File "/usr/src/homeassistant/homeassistant/components/blink/binary_sensor.py", line 74, in update
    self.data.refresh()
  File "/usr/local/lib/python3.10/site-packages/blinkpy/helpers/util.py", line 144, in wrapper
    result = method(*args, *kwargs)
  File "/usr/local/lib/python3.10/site-packages/blinkpy/blinkpy.py", line 93, in refresh
    sync_module.refresh(force_cache=(force or force_cache))
  File "/usr/local/lib/python3.10/site-packages/blinkpy/sync_module.py", line 207, in refresh
    self.cameras[camera_name].update(camera_info, force_cache=force_cache)
  File "/usr/local/lib/python3.10/site-packages/blinkpy/camera.py", line 141, in update
    self.extract_config_info(config)
  File "/usr/local/lib/python3.10/site-packages/blinkpy/camera.py", line 147, in extract_config_info
    self.name = config.get("name", "unknown")
AttributeError: 'NoneType' object has no attribute 'get'
2023-01-24 14:13:00.508 ERROR (MainThread) [homeassistant.helpers.entity] Update for sensor.blink_garage_temperature fails
Traceback (most recent call last):
  File "/usr/src/homeassistant/homeassistant/helpers/entity.py", line 538, in async_update_ha_state
    await self.async_device_update()
  File "/usr/src/homeassistant/homeassistant/helpers/entity.py", line 736, in async_device_update
    raise exc
  File "/usr/local/lib/python3.10/concurrent/futures/thread.py", line 58, in run
    result = self.fn(*self.args, **self.kwargs)
  File "/usr/src/homeassistant/homeassistant/components/blink/sensor.py", line 77, in update
    self.data.refresh()
  File "/usr/local/lib/python3.10/site-packages/blinkpy/helpers/util.py", line 144, in wrapper
    result = method(*args, *kwargs)
  File "/usr/local/lib/python3.10/site-packages/blinkpy/blinkpy.py", line 93, in refresh
    sync_module.refresh(force_cache=(force or force_cache))
  File "/usr/local/lib/python3.10/site-packages/blinkpy/sync_module.py", line 207, in refresh
    self.cameras[camera_name].update(camera_info, force_cache=force_cache)
  File "/usr/local/lib/python3.10/site-packages/blinkpy/camera.py", line 141, in update
    self.extract_config_info(config)
  File "/usr/local/lib/python3.10/site-packages/blinkpy/camera.py", line 147, in extract_config_info
    self.name = config.get("name", "unknown")
AttributeError: 'NoneType' object has no attribute 'get'
2023-01-24 14:13:00.553 ERROR (MainThread) [homeassistant.helpers.entity] Update for binary_sensor.blink_garage_camera_armed fails
Traceback (most recent call last):
  File "/usr/src/homeassistant/homeassistant/helpers/entity.py", line 538, in async_update_ha_state
    await self.async_device_update()
  File "/usr/src/homeassistant/homeassistant/helpers/entity.py", line 736, in async_device_update
    raise exc
  File "/usr/local/lib/python3.10/concurrent/futures/thread.py", line 58, in run
    result = self.fn(*self.args, **self.kwargs)
  File "/usr/src/homeassistant/homeassistant/components/blink/binary_sensor.py", line 74, in update
    self.data.refresh()
  File "/usr/local/lib/python3.10/site-packages/blinkpy/helpers/util.py", line 144, in wrapper
    result = method(*args, *kwargs)
  File "/usr/local/lib/python3.10/site-packages/blinkpy/blinkpy.py", line 93, in refresh
    sync_module.refresh(force_cache=(force or force_cache))
  File "/usr/local/lib/python3.10/site-packages/blinkpy/sync_module.py", line 207, in refresh
    self.cameras[camera_name].update(camera_info, force_cache=force_cache)
  File "/usr/local/lib/python3.10/site-packages/blinkpy/camera.py", line 141, in update
    self.extract_config_info(config)
  File "/usr/local/lib/python3.10/site-packages/blinkpy/camera.py", line 147, in extract_config_info
    self.name = config.get("name", "unknown")
AttributeError: 'NoneType' object has no attribute 'get'
2023-01-24 14:13:00.565 ERROR (MainThread) [homeassistant.helpers.entity] Update for sensor.blink_garage_wifi_signal fails
Traceback (most recent call last):
  File "/usr/src/homeassistant/homeassistant/helpers/entity.py", line 538, in async_update_ha_state
    await self.async_device_update()
  File "/usr/src/homeassistant/homeassistant/helpers/entity.py", line 736, in async_device_update
    raise exc
  File "/usr/local/lib/python3.10/concurrent/futures/thread.py", line 58, in run
    result = self.fn(*self.args, **self.kwargs)
  File "/usr/src/homeassistant/homeassistant/components/blink/sensor.py", line 77, in update
    self.data.refresh()
  File "/usr/local/lib/python3.10/site-packages/blinkpy/helpers/util.py", line 144, in wrapper
    result = method(*args, *kwargs)
  File "/usr/local/lib/python3.10/site-packages/blinkpy/blinkpy.py", line 93, in refresh
    sync_module.refresh(force_cache=(force or force_cache))
  File "/usr/local/lib/python3.10/site-packages/blinkpy/sync_module.py", line 207, in refresh
    self.cameras[camera_name].update(camera_info, force_cache=force_cache)
  File "/usr/local/lib/python3.10/site-packages/blinkpy/camera.py", line 141, in update
    self.extract_config_info(config)
  File "/usr/local/lib/python3.10/site-packages/blinkpy/camera.py", line 147, in extract_config_info
    self.name = config.get("name", "unknown")
AttributeError: 'NoneType' object has no attribute 'get'
2023-01-24 14:13:00.613 ERROR (MainThread) [homeassistant.helpers.entity] Update for binary_sensor.blink_garage_motion_detected fails
Traceback (most recent call last):
  File "/usr/src/homeassistant/homeassistant/helpers/entity.py", line 538, in async_update_ha_state
    await self.async_device_update()
  File "/usr/src/homeassistant/homeassistant/helpers/entity.py", line 736, in async_device_update
    raise exc
  File "/usr/local/lib/python3.10/concurrent/futures/thread.py", line 58, in run
    result = self.fn(*self.args, **self.kwargs)
  File "/usr/src/homeassistant/homeassistant/components/blink/binary_sensor.py", line 74, in update
    self.data.refresh()
  File "/usr/local/lib/python3.10/site-packages/blinkpy/helpers/util.py", line 144, in wrapper
    result = method(*args, *kwargs)
  File "/usr/local/lib/python3.10/site-packages/blinkpy/blinkpy.py", line 93, in refresh
    sync_module.refresh(force_cache=(force or force_cache))
  File "/usr/local/lib/python3.10/site-packages/blinkpy/sync_module.py", line 207, in refresh
    self.cameras[camera_name].update(camera_info, force_cache=force_cache)
  File "/usr/local/lib/python3.10/site-packages/blinkpy/camera.py", line 141, in update
    self.extract_config_info(config)
  File "/usr/local/lib/python3.10/site-packages/blinkpy/camera.py", line 147, in extract_config_info
    self.name = config.get("name", "unknown")
AttributeError: 'NoneType' object has no attribute 'get'
2023-01-24 14:14:00.425 ERROR (MainThread) [homeassistant.components.automation.auto_trigger_camera] Auto Trigger Camera: Error executing script. Unexpected error for call_service at pos 1: 'NoneType' object has no attribute 'get'
Traceback (most recent call last):
  File "/usr/src/homeassistant/homeassistant/helpers/script.py", line 451, in _async_step
    await getattr(self, handler)()
  File "/usr/src/homeassistant/homeassistant/helpers/script.py", line 684, in _async_call_service_step
    await service_task
  File "/usr/src/homeassistant/homeassistant/core.py", line 1755, in async_call
    task.result()
  File "/usr/src/homeassistant/homeassistant/core.py", line 1792, in _execute_service
    await cast(Callable[[ServiceCall], Awaitable[None]], handler.job.target)(
  File "/usr/src/homeassistant/homeassistant/helpers/entity_platform.py", line 787, in handle_service
    await service.entity_service_call(
  File "/usr/src/homeassistant/homeassistant/helpers/service.py", line 678, in entity_service_call
    future.result()  # pop exception if have
  File "/usr/src/homeassistant/homeassistant/helpers/entity.py", line 958, in async_request_call
    await coro
  File "/usr/src/homeassistant/homeassistant/helpers/service.py", line 715, in _handle_entity_call
    await result
  File "/usr/local/lib/python3.10/concurrent/futures/thread.py", line 58, in run
    result = self.fn(*self.args, **self.kwargs)
  File "/usr/src/homeassistant/homeassistant/components/blink/camera.py", line 84, in trigger_camera
    self.data.refresh()
  File "/usr/local/lib/python3.10/site-packages/blinkpy/helpers/util.py", line 144, in wrapper
    result = method(*args, *kwargs)
  File "/usr/local/lib/python3.10/site-packages/blinkpy/blinkpy.py", line 93, in refresh
    sync_module.refresh(force_cache=(force or force_cache))
  File "/usr/local/lib/python3.10/site-packages/blinkpy/sync_module.py", line 207, in refresh
    self.cameras[camera_name].update(camera_info, force_cache=force_cache)
  File "/usr/local/lib/python3.10/site-packages/blinkpy/camera.py", line 141, in update
    self.extract_config_info(config)
  File "/usr/local/lib/python3.10/site-packages/blinkpy/camera.py", line 147, in extract_config_info
    self.name = config.get("name", "unknown")
AttributeError: 'NoneType' object has no attribute 'get'
2023-01-24 14:14:00.430 ERROR (MainThread) [homeassistant.components.automation.auto_trigger_camera] While executing automation automation.auto_trigger_camera
Traceback (most recent call last):
  File "/usr/src/homeassistant/homeassistant/components/automation/__init__.py", line 546, in async_trigger
    await self.action_script.async_run(
  File "/usr/src/homeassistant/homeassistant/helpers/script.py", line 1524, in async_run
    await asyncio.shield(run.async_run())
  File "/usr/src/homeassistant/homeassistant/helpers/script.py", line 409, in async_run
    await self._async_step(log_exceptions=False)
  File "/usr/src/homeassistant/homeassistant/helpers/script.py", line 453, in _async_step
    self._handle_exception(
  File "/usr/src/homeassistant/homeassistant/helpers/script.py", line 476, in _handle_exception
    raise exception
  File "/usr/src/homeassistant/homeassistant/helpers/script.py", line 451, in _async_step
    await getattr(self, handler)()
  File "/usr/src/homeassistant/homeassistant/helpers/script.py", line 684, in _async_call_service_step
    await service_task
  File "/usr/src/homeassistant/homeassistant/core.py", line 1755, in async_call
    task.result()
  File "/usr/src/homeassistant/homeassistant/core.py", line 1792, in _execute_service
    await cast(Callable[[ServiceCall], Awaitable[None]], handler.job.target)(
  File "/usr/src/homeassistant/homeassistant/helpers/entity_platform.py", line 787, in handle_service
    await service.entity_service_call(
  File "/usr/src/homeassistant/homeassistant/helpers/service.py", line 678, in entity_service_call
    future.result()  # pop exception if have
  File "/usr/src/homeassistant/homeassistant/helpers/entity.py", line 958, in async_request_call
    await coro
  File "/usr/src/homeassistant/homeassistant/helpers/service.py", line 715, in _handle_entity_call
    await result
  File "/usr/local/lib/python3.10/concurrent/futures/thread.py", line 58, in run
    result = self.fn(*self.args, **self.kwargs)
  File "/usr/src/homeassistant/homeassistant/components/blink/camera.py", line 84, in trigger_camera
    self.data.refresh()
  File "/usr/local/lib/python3.10/site-packages/blinkpy/helpers/util.py", line 144, in wrapper
    result = method(*args, *kwargs)
  File "/usr/local/lib/python3.10/site-packages/blinkpy/blinkpy.py", line 93, in refresh
    sync_module.refresh(force_cache=(force or force_cache))
  File "/usr/local/lib/python3.10/site-packages/blinkpy/sync_module.py", line 207, in refresh
    self.cameras[camera_name].update(camera_info, force_cache=force_cache)
  File "/usr/local/lib/python3.10/site-packages/blinkpy/camera.py", line 141, in update
    self.extract_config_info(config)
  File "/usr/local/lib/python3.10/site-packages/blinkpy/camera.py", line 147, in extract_config_info
    self.name = config.get("name", "unknown")
AttributeError: 'NoneType' object has no attribute 'get'
2023-01-24 14:14:00.437 ERROR (MainThread) [homeassistant.helpers.entity] Update for binary_sensor.blink_garage_battery fails
Traceback (most recent call last):
  File "/usr/src/homeassistant/homeassistant/helpers/entity.py", line 538, in async_update_ha_state
    await self.async_device_update()
  File "/usr/src/homeassistant/homeassistant/helpers/entity.py", line 736, in async_device_update
    raise exc
  File "/usr/local/lib/python3.10/concurrent/futures/thread.py", line 58, in run
    result = self.fn(*self.args, **self.kwargs)
  File "/usr/src/homeassistant/homeassistant/components/blink/binary_sensor.py", line 74, in update
    self.data.refresh()
  File "/usr/local/lib/python3.10/site-packages/blinkpy/helpers/util.py", line 144, in wrapper
    result = method(*args, *kwargs)
  File "/usr/local/lib/python3.10/site-packages/blinkpy/blinkpy.py", line 93, in refresh
    sync_module.refresh(force_cache=(force or force_cache))
  File "/usr/local/lib/python3.10/site-packages/blinkpy/sync_module.py", line 207, in refresh
    self.cameras[camera_name].update(camera_info, force_cache=force_cache)
  File "/usr/local/lib/python3.10/site-packages/blinkpy/camera.py", line 141, in update
    self.extract_config_info(config)
  File "/usr/local/lib/python3.10/site-packages/blinkpy/camera.py", line 147, in extract_config_info
    self.name = config.get("name", "unknown")
AttributeError: 'NoneType' object has no attribute 'get'
2023-01-24 14:14:00.487 ERROR (MainThread) [homeassistant.helpers.entity] Update for sensor.blink_garage_temperature fails
Traceback (most recent call last):
  File "/usr/src/homeassistant/homeassistant/helpers/entity.py", line 538, in async_update_ha_state
    await self.async_device_update()
  File "/usr/src/homeassistant/homeassistant/helpers/entity.py", line 736, in async_device_update
    raise exc
  File "/usr/local/lib/python3.10/concurrent/futures/thread.py", line 58, in run
    result = self.fn(*self.args, **self.kwargs)
  File "/usr/src/homeassistant/homeassistant/components/blink/sensor.py", line 77, in update
    self.data.refresh()
  File "/usr/local/lib/python3.10/site-packages/blinkpy/helpers/util.py", line 144, in wrapper
    result = method(*args, *kwargs)
  File "/usr/local/lib/python3.10/site-packages/blinkpy/blinkpy.py", line 93, in refresh
    sync_module.refresh(force_cache=(force or force_cache))
  File "/usr/local/lib/python3.10/site-packages/blinkpy/sync_module.py", line 207, in refresh
    self.cameras[camera_name].update(camera_info, force_cache=force_cache)
  File "/usr/local/lib/python3.10/site-packages/blinkpy/camera.py", line 141, in update
    self.extract_config_info(config)
  File "/usr/local/lib/python3.10/site-packages/blinkpy/camera.py", line 147, in extract_config_info
    self.name = config.get("name", "unknown")
AttributeError: 'NoneType' object has no attribute 'get'
2023-01-24 14:14:00.506 ERROR (MainThread) [homeassistant.helpers.entity] Update for alarm_control_panel.blink_garage fails
Traceback (most recent call last):
  File "/usr/src/homeassistant/homeassistant/helpers/entity.py", line 538, in async_update_ha_state
    await self.async_device_update()
  File "/usr/src/homeassistant/homeassistant/helpers/entity.py", line 736, in async_device_update
    raise exc
  File "/usr/local/lib/python3.10/concurrent/futures/thread.py", line 58, in run
    result = self.fn(*self.args, **self.kwargs)
  File "/usr/src/homeassistant/homeassistant/components/blink/alarm_control_panel.py", line 59, in update
    self.data.refresh()
  File "/usr/local/lib/python3.10/site-packages/blinkpy/helpers/util.py", line 144, in wrapper
    result = method(*args, *kwargs)
  File "/usr/local/lib/python3.10/site-packages/blinkpy/blinkpy.py", line 93, in refresh
    sync_module.refresh(force_cache=(force or force_cache))
  File "/usr/local/lib/python3.10/site-packages/blinkpy/sync_module.py", line 207, in refresh
    self.cameras[camera_name].update(camera_info, force_cache=force_cache)
  File "/usr/local/lib/python3.10/site-packages/blinkpy/camera.py", line 141, in update
    self.extract_config_info(config)
  File "/usr/local/lib/python3.10/site-packages/blinkpy/camera.py", line 147, in extract_config_info
    self.name = config.get("name", "unknown")
AttributeError: 'NoneType' object has no attribute 'get'
2023-01-24 14:14:00.509 ERROR (MainThread) [homeassistant.helpers.entity] Update for binary_sensor.blink_garage_camera_armed fails
Traceback (most recent call last):
  File "/usr/src/homeassistant/homeassistant/helpers/entity.py", line 538, in async_update_ha_state
    await self.async_device_update()
  File "/usr/src/homeassistant/homeassistant/helpers/entity.py", line 736, in async_device_update
    raise exc
  File "/usr/local/lib/python3.10/concurrent/futures/thread.py", line 58, in run
    result = self.fn(*self.args, **self.kwargs)
  File "/usr/src/homeassistant/homeassistant/components/blink/binary_sensor.py", line 74, in update
    self.data.refresh()
  File "/usr/local/lib/python3.10/site-packages/blinkpy/helpers/util.py", line 144, in wrapper
    result = method(*args, *kwargs)
  File "/usr/local/lib/python3.10/site-packages/blinkpy/blinkpy.py", line 93, in refresh
    sync_module.refresh(force_cache=(force or force_cache))
  File "/usr/local/lib/python3.10/site-packages/blinkpy/sync_module.py", line 207, in refresh
    self.cameras[camera_name].update(camera_info, force_cache=force_cache)
  File "/usr/local/lib/python3.10/site-packages/blinkpy/camera.py", line 141, in update
    self.extract_config_info(config)
  File "/usr/local/lib/python3.10/site-packages/blinkpy/camera.py", line 147, in extract_config_info
    self.name = config.get("name", "unknown")
AttributeError: 'NoneType' object has no attribute 'get'
2023-01-24 14:14:00.552 ERROR (MainThread) [homeassistant.helpers.entity] Update for sensor.blink_garage_wifi_signal fails
Traceback (most recent call last):
  File "/usr/src/homeassistant/homeassistant/helpers/entity.py", line 538, in async_update_ha_state
    await self.async_device_update()
  File "/usr/src/homeassistant/homeassistant/helpers/entity.py", line 736, in async_device_update
    raise exc
  File "/usr/local/lib/python3.10/concurrent/futures/thread.py", line 58, in run
    result = self.fn(*self.args, **self.kwargs)
  File "/usr/src/homeassistant/homeassistant/components/blink/sensor.py", line 77, in update
    self.data.refresh()
  File "/usr/local/lib/python3.10/site-packages/blinkpy/helpers/util.py", line 144, in wrapper
    result = method(*args, *kwargs)
  File "/usr/local/lib/python3.10/site-packages/blinkpy/blinkpy.py", line 93, in refresh
    sync_module.refresh(force_cache=(force or force_cache))
  File "/usr/local/lib/python3.10/site-packages/blinkpy/sync_module.py", line 207, in refresh
    self.cameras[camera_name].update(camera_info, force_cache=force_cache)
  File "/usr/local/lib/python3.10/site-packages/blinkpy/camera.py", line 141, in update
    self.extract_config_info(config)
  File "/usr/local/lib/python3.10/site-packages/blinkpy/camera.py", line 147, in extract_config_info
    self.name = config.get("name", "unknown")
AttributeError: 'NoneType' object has no attribute 'get'
2023-01-24 14:14:00.571 ERROR (MainThread) [homeassistant.helpers.entity] Update for binary_sensor.blink_garage_motion_detected fails
Traceback (most recent call last):
  File "/usr/src/homeassistant/homeassistant/helpers/entity.py", line 538, in async_update_ha_state
    await self.async_device_update()
  File "/usr/src/homeassistant/homeassistant/helpers/entity.py", line 736, in async_device_update
    raise exc
  File "/usr/local/lib/python3.10/concurrent/futures/thread.py", line 58, in run
    result = self.fn(*self.args, **self.kwargs)
  File "/usr/src/homeassistant/homeassistant/components/blink/binary_sensor.py", line 74, in update
    self.data.refresh()
  File "/usr/local/lib/python3.10/site-packages/blinkpy/helpers/util.py", line 144, in wrapper
    result = method(*args, *kwargs)
  File "/usr/local/lib/python3.10/site-packages/blinkpy/blinkpy.py", line 93, in refresh
    sync_module.refresh(force_cache=(force or force_cache))
  File "/usr/local/lib/python3.10/site-packages/blinkpy/sync_module.py", line 207, in refresh
    self.cameras[camera_name].update(camera_info, force_cache=force_cache)
  File "/usr/local/lib/python3.10/site-packages/blinkpy/camera.py", line 141, in update
    self.extract_config_info(config)
  File "/usr/local/lib/python3.10/site-packages/blinkpy/camera.py", line 147, in extract_config_info
    self.name = config.get("name", "unknown")
AttributeError: 'NoneType' object has no attribute 'get'
